Workbook

Sheet All
A1: Process | B1: Category | C1: GWP | D1: Human health | E1: Ecosystems | F1: Resources
A2: BAU | B2: BAU | C2: 6.1267694 | D2: 1.5002653e-05 | E2: 3.1124968e-08 | F2: 0.64467457
A3: BAU | B3: Natural gas | C3: 0 | D3: 0 | E3: 0 | F3: 0
A4: BAU | B4: Carbon dioxide | C4: 0 | D4: 0 | E4: 0 | F4: 0
A5: BAU | B5: Biogas | C5: 0 | D5: 0 | E5: 0 | F5: 0
A6: BAU | B6: Oxygen | C6: 0 | D6: 0 | E6: 0 | F6: 0
A7: BAU | B7: Hydrogen | C7: 0 | D7: 0 | E7: 0 | F7: 0
A8: BAU | B8: Ethylene | C8: 0 | D8: 0 | E8: 0 | F8: 0
A9: BAU | B9: Utilities + fixed costs | C9: 0 | D9: 0 | E9: 0 | F9: 0
A10: BAU | B10: CAPEX | C10: 0 | D10: 0 | E10: 0 | F10: 0
A11: NG + wind | B11: BAU | C11: 0 | D11: 0 | E11: 0 | F11: 0
A12: NG + wind | B12: Natural gas | C12: 0 | D12: 0 | E12: 0 | F12: 0
A13: NG + wind | B13: Carbon dioxide | C13: 0.074845913 | D13: 1.2125559e-07 | E13: 3.2270254e-10 | F13: 0.022496144
... A53: Biogas | B53: Ethylene | C53: 0.71561645 | D53: 1.00974e-06 | E53: 2.5784447e-09 | F53: 0.28266307
A54: Biogas | B54: Utilities + fixed costs | C54: =1.36155937821+0.0084 -> 1.3699594 | D54: 2.41e-06 | E54: 5.25e-09 | F54: 0.146
A55: Biogas | B55: CAPEX | C55: 0 | D55: 0 | E55: 0 | F55: 0
A56: Biogas + gE - NG | B56: BAU | C56: 0 | D56: 0 | E56: 0 | F56: 0
A57: Biogas + gE - NG | B57: Natural gas | C57: 0 | D57: 0 | E57: 0 | F57: 0
A58: Biogas + gE - NG | B58: Carbon dioxide | C58: 0 | D58: 0 | E58: 0 | F58: 0
A59: Biogas + gE - NG | B59: Biogas | C59: -0.8974496 | D59: -8.3283323e-07 | E59: -2.5129275e-09 | F59: 0
A60: Biogas + gE - NG | B60: Oxygen | C60: 0 | D60: 0 | E60: 0 | F60: 0
A61: Biogas + gE - NG | B61: Hydrogen | C61: 0 | D61: 0 | E61: 0 | F61: 0
A62: Biogas + gE - NG | B62: Ethylene | C62: 0.97501398 | D62: 3.0069607e-06 | E62: 4.6317401e-09 | F62: 0.086765957
A63: Biogas + gE - NG | B63: Utilities + fixed costs | C63: =1.36155937821+0.0084 -> 1.3699594 | D63: 2.41e-06 | E63: 5.25e-09 | F63: 0.146
A64: Biogas + gE - NG | B64: CAPEX | C64: 0 | D64: 0 | E64: 0 | F64: 0
A65: Biogas + gE - DAC | B65: BAU | C65: 0 | D65: 0 | E65: 0 | F65: 0
A66: Biogas + gE - DAC | B66: Natural gas | C66: 0 | D66: 0 | E66: 0 | F66: 0
A67: Biogas + gE - DAC | B67: Carbon dioxide | C67: 0 | D67: 0 | E67: 0 | F67: 0
A68: Biogas + gE - DAC | B68: Biogas | C68: -0.8974496 | D68: -8.3283323e-07 | E68: -2.5129275e-09 | F68: 0
A69: Biogas + gE - DAC | B69: Oxygen | C69: 0 | D69: 0 | E69: 0 | F69: 0
A70: Biogas + gE - DAC | B70: Hydrogen | C70: 0 | D70: 0 | E70: 0 | F70: 0
A71: Biogas + gE - DAC | B71: Ethylene | C71: -0.42322445 | D71: 1.7328535e-06 | E71: 6.58713e-10 | F71: 0.11199007
A72: Biogas + gE - DAC | B72: Utilities + fixed costs | C72: =1.36155937821+0.0084 -> 1.3699594 | D72: 2.41e-06 | E72: 5.25e-09 | F72: 0.146
A73: Biogas + gE - DAC | B73: CAPEX | C73: 0 | D73: 0 | E73: 0 | F73: 0
A74: Biogas + bioE | B74: BAU | C74: 0 | D74: 0 | E74: 0 | F74: 0
A75: Biogas + bioE | B75: Natural gas | C75: 0 | D75: 0 | E75: 0 | F75: 0
A76: Biogas + bioE | B76: Carbon dioxide | C76: 0 | D76: 0 | E76: 0 | F76: 0
A77: Biogas + bioE | B77: Biogas | C77: -0.8974496 | D77: -8.3283323e-07 | E77: -2.5129275e-09 | F77: 0
A78: Biogas + bioE | B78: Oxygen | C78: 0 | D78: 0 | E78: 0 | F78: 0
A79: Biogas + bioE | B79: Hydrogen | C79: 0 | D79: 0 | E79: 0 | F79: 0
...

Sheet Cummulative
A1: Process | B1: yCoordinate | C1: GWP | D1: Human health | E1: Ecosystems | F1: Resources
A2: BAU | B2: 0
A3: NG + wind | B3: =B2+1 -> 1 | C3: =SUM(All!C11:C19) -> 1.1309037 | D3: =SUM(All!D11:D19) -> 2.4867036e-06 | E3: =SUM(All!E11:E19) -> 4.8119711e-09 | F3: =SUM(All!F11:F19) -> 0.334807
A4: DAC + wind | B4: =B3+1 -> 2 | C4: =SUM(All!C20:C28) -> 0.54300743 | D4: =SUM(All!D20:D28) -> 1.950999e-06 | E4: =SUM(All!E20:E28) -> 3.1414923e-09 | F4: =SUM(All!F20:F28) -> 0.3454126
A5: NG + wind + gE | B5: =B4+1 -> 3 | C5: =SUM(All!C29:C37) -> 1.3907358 | D5: =SUM(All!D29:D37) -> 4.4940624e-06 | E5: =SUM(All!E29:E37) -> 6.8756892e-09 | F5: =SUM(All!F29:F37) -> 0.13791548
A6: DAC + wind + gE | B6: =B5+1 -> 4 | C6: =SUM(All!C38:C46) -> -0.60249649 | D6: =SUM(All!D38:D46) -> 2.6777831e-06 | E6: =SUM(All!E38:E46) -> 1.2120158e-09 | F6: =SUM(All!F38:F46) -> 0.17387324
A7: Biogas | B7: =B6+1 -> 5 | C7: =SUM(All!C47:C55) -> 1.1881262 | D7: =SUM(All!D47:D55) -> 2.5869068e-06 | E7: =SUM(All!E47:E55) -> 5.3155172e-09 | F7: =SUM(All!F47:F55) -> 0.42866307
A8: Biogas + gE - NG | B8: =B7+1 -> 6 | C8: =SUM(All!C56:C64) -> 1.4475238 | D8: =SUM(All!D56:D64) -> 4.5841275e-06 | E8: =SUM(All!E56:E64) -> 7.3688126e-09 | F8: =SUM(All!F56:F64) -> 0.23276596
A9: Biogas + gE - DAC | B9: =B8+1 -> 7 | C9: =SUM(All!C65:C73) -> 0.049285328 | D9: =SUM(All!D65:D73) -> 3.3100203e-06 | E9: =SUM(All!E65:E73) -> 3.3957855e-09 | F9: =SUM(All!F65:F73) -> 0.25799007
A10: Biogas + bE | B10: =B9+1 -> 8 | C10: =SUM(All!C74:C82) -> -2.1029756 | D10: =SUM(All!D74:D82) -> 1.3652961e-06 | E10: =SUM(All!E74:E82) -> -1.7956971e-09 | F10: =SUM(All!F74:F82) -> 0.47206357
