Workbook

Sheet LCI_Biogas
A1: Database | B1: Biogas-to-Chemicals
A3: Activity | B3: treatment of biowaste by anaerobic digestion, cut-off with biogenic carbon uptake
A4: comment | B4: This dataset represents the production of biogas by anaerobic digestion of biowaste (food and green waste) in Europe. Biogas is a by-product of the main activity (biowaste treatment) and comes free of burdens. The dataset was adapted to include the corresponding CO2 removed from the atmosphere during biomass growth and contained in the biogas. This ensures the carbon neutrality of the biogas supply chain from cradle to grave
A5: location | B5: RER
A6: reference product | B6: biogas
A7: production amount | B7: 1
A8: unit | B8: cubic meter
A9: source
A10: Exchanges
A11: name | B11: reference product | C11: amount | D11: unit | E11: database | F11: categories | G11: location | H11: type | I11: comment
A12: treatment of biowaste by anaerobic digestion, cut-off with biogenic carbon uptake | B12: biogas | C12: 1 | D12: cubic meter | E12: Biogas-to-Chemicals | G12: RER | H12: production
A13: Carbon dioxide, to soil or biomass stock | C13: ='Carbon balance'!$C$10 -> 1.98185 | D13: kilogram | E13: biosphere3 | F13: soil | H13: biosphere | I13: amount of CO2 removed from the atmosphere during biomass growth and contained in the biogas; see Carbon balance
A15: Activity | B15: treatment of sewage sludge by anaerobic digestion, cut-off with biogenic carbon uptake
A16: comment | B16: This dataset represents the production of biogas by anaerobic digestion of sewage sludge in Europe. Biogas is a by-product of the main activity (wastewater treatment) and comes free of burdens. The dataset was adapted to include the corresponding CO2 removed from the atmosphere during biomass growth and contained in the biogas. This ensures the carbon neutrality of the biogas supply chain from cradle to grave
A17: location | B17: RER
A18: reference product | B18: biogas
A19: production amount | B19: 1
A20: unit | B20: cubic meter
A21: source
A22: Exchanges
A23: name | B23: reference product | C23: amount | D23: unit | E23: database | F23: categories | G23: location | H23: type | I23: comment
A24: treatment of sewage sludge by anaerobic digestion, cut-off with biogenic carbon uptake | B24: biogas | C24: 1 | D24: cubic meter | E24: Biogas-to-Chemicals | G24: RER | H24: production
A25: Carbon dioxide, to soil or biomass stock | C25: ='Carbon balance'!$E$10 -> 1.98185 | D25: kilogram | E25: biosphere3 | F25: soil | H25: biosphere | I25: amount of CO2 removed from the atmosphere during biomass growth and contained in the biogas; see Carbon balance
A27: Activity | B27: anaerobic digestion of animal manure, with biogenic carbon uptake
A28: comment | B28: This dataset represents the production of biogas and digestate by anaerobic digestion of animal manure in Europe. Biogas is the single purpose of this process and, therefore, all the environmental burdens of waste treatment are allocated to the biogas (i.e., digestate leaves the process free of burdens). Manure was assumed to come free of burdens (no collection nor transportation was assumed to be needed). The dataset was adapted to include the corresponding CO2 removed from the atmosphere during biomass growth and contained in the biogas. This ensures the carbon neutrality of the biogas supply chain from cradle to grave
A29: location | B29: RER
A30: reference product | B30: biogas
A31: production amount | B31: 1
A32: unit | B32: cubic meter
A33: source
A34: Exchanges
A35: name | B35: reference product | C35: amount | D35: unit | E35: database | F35: categories | G35: location | H35: type | I35: comment
A36: anaerobic digestion of animal manure, with biogenic carbon uptake | B36: biogas | C36: 1 | D36: cubic meter | E36: Biogas-to-Chemicals | G36: RER | H36: production
A37: market group for electricity, low voltage | B37: electricity, low voltage | C37: 0.158 | D37: kilowatt hour | E37: ecoinvent | G37: RER | H37: technosphere | I37: ecoinvent default data
A38: market for heat, central or small-scale, other than natural gas | B38: heat, central or small-scale, other than natural gas | C38: 3.47 | D38: megajoule | E38: ecoinvent | G38: Europe without Switzerland | H38: technosphere | I38: ecoinvent default data
A39: anaerobic digestion plant construction, agriculture, with methane recovery | B39: anaerobic digestion plant, agriculture, with methane recovery | C39: 2.860003e-07 | D39: unit | E39: ecoinvent | G39: RoW | H39: technosphere | I39: ecoinvent default data
A40: digester sludge, Recycled Content cut-off | B40: digester sludge | C40: -36.182574 | D40: kilogram | E40: ecoinvent | G40: GLO | H40: technosphere | I40: ecoinvent default data
A41: Carbon dioxide, to soil or biomass stock | C41: ='Carbon balance'!$B$10 -> 1.98185 | D41: kilogram | E41: biosphere3 | F41: soil | H41: biosphere | I41: amount of CO2 removed from the atmosphere during biomass growth and contained in the biogas; see Carbon balance
A42: Carbon dioxide, non-fossil | C42: 0.070895249 | D42: kilogram | E42: biosphere3 | F42: air::non-urban air or from high stacks | H42: biosphere | I42: ecoinvent default data
A43: Methane, non-fossil | C43: 0.019834232 | D43: kilogram | E43: biosphere3 | F43: air::non-urban air or from high stacks | H43: biosphere | I43: ecoinvent default data
...

Sheet LCI_Biomethane_2
A2: Activity | B2: market group for biomethane, high pressure
A3: comment
A4: location | B4: RER
A5: reference product | B5: biomethane, high pressure
A6: production amount | B6: 1
A7: unit | B7: cubic meter
A8: source
A9: Exchanges
A10: name | B10: reference product | C10: amount | D10: unit | E10: database | F10: categories | G10: location | H10: type | I10: comment
A11: market group for biomethane, high pressure | B11: biomethane, high pressure | C11: 1 | D11: cubic meter | E11: Biogas-to-Chemicals | G11: RER | H11: production

Sheet LCI_Biomethane
A1: Database | B1: biogas to chemicals
A3: Activity | B3: treatment of biowaste by anaerobic digestion, cut-off with biogenic carbon uptake
A4: comment | B4: This dataset represents the production of biogas by anaerobic digestion of biowaste. Biogas is a by-product of the main activity (biowaste treatment) and comes free of burdens. Dataset was adapted to include the CO2 removed from the atmosphere during biomass growth. This ensures the carbon neutrality of biogas supply chains. Only the carbon removed from the atmosphere and transferred into the biogas was considered
A5: location | B5: RER
A6: reference product | B6: biogas
A7: production amount | B7: 1
A8: unit | B8: cubic meter
A9: source
A10: Exchanges
A11: name | B11: reference product | C11: amount | D11: unit | E11: database | F11: categories | G11: location | H11: type | I11: comment
A12: treatment of biowaste by anaerobic digestion, cut-off with biogenic carbon uptake | B12: biogas | C12: 1 | D12: cubic meter | E12: biogas to chemicals | G12: RER | H12: production | I12: assume biogas composition 60% CH4 and 40% CO2
A13: Carbon dioxide, to soil or biomass stock | C13: ='Carbon balance'!$D$10 -> 1.98185 | D13: kilogram | E13: biosphere3 | F13: soil | H13: biosphere | I13: amount of CO2 removed from the atmosphere per cubic meter of biogas during biomass growth; see Carbon balance
A15: Activity | B15: biogas upgrading to biomethane, pressure swing adsorption
A16: comment | B16: This dataset represents the upgrading of biogas to biomethane using the pressure swing adsorption (PSA) technology
A17: location | B17: RER
A18: reference product | B18: biomethane, high pressure
A19: production amount | B19: 1
A20: unit | B20: cubic meter
A21: source | B21: Based on the equivalent dataset from ecoinvent v3.8. Electricity consumption was updated and the input volume of biogas and emissions of CH4 and CO2 were recalculated based on the carbon balance
A22: Exchanges
A23: name | B23: reference product | C23: amount | D23: unit | E23: database | F23: categories | G23: location | H23: type | I23: comment
A24: biogas upgrading to biomethane, pressure swing adsorption | B24: biomethane, high pressure | C24: 1 | D24: cubic meter | E24: biogas to chemicals | G24: RER | H24: production | I24: 98% purity (98% CH4 and 2% CO2 v/v)
A25: treatment of biowaste by anaerobic digestion, cut-off with biogenic carbon uptake | B25: biogas | C25: ='Carbon balance'!$B$20 -> 1.666 | D25: cubic meter | E25: biogas to chemicals | G25: RER | H25: technosphere | I25: see Carbon balance
A26: market group for electricity, medium voltage | B26: electricity, medium voltage | C26: =AVERAGE(0.15,0.3)*C25 -> 0.37485 | D26: kilowatt hour | E26: ecoinvent | G26: RER | H26: technosphere | I26: overall electricity consumption required for PSA upgrading (including compression up to natural gas network requirements); average value (0.15-0.30 kWh/m3 biogas) based on Bauer 2013
A27: chemical factory construction, organics | B27: chemical factory, organics | C27: 5.4e-11 | D27: unit | E27: ecoinvent | G27: RER | H27: technosphere | I27: ecoinvent default data
A28: market for lubricating oil | B28: lubricating oil | C28: 0.00015 | D28: kilogram | E28: ecoinvent | G28: RER | H28: technosphere | I28: ecoinvent default data
A29: market for potassium hydroxide | B29: potassium hydroxide | C29: 3.98e-06 | D29: kilogram | E29: ecoinvent | G29: GLO | H29: technosphere | I29: ecoinvent default data
A30: Carbon dioxide, non-fossil | C30: ='Carbon balance'!$B$22 -> 1.3041848 | D30: kilogram | E30: biosphere3 | F30: air::non-urban air or from high stacks | H30: biosphere | I30: assume 2% of CO2 in biogas remains in biomethane and the rest is removed and released to the atmosphere (no CCS); see Carbon balance
A31: Methane, non-fossil | C31: ='Carbon balance'!$B$21 -> 0.014334264 | D31: kilogram | E31: biosphere3 | F31: air::non-urban air or from high stacks | H31: biosphere | I31: assume 2% methane leakage; see Carbon balance
A32: Nitrogen | C32: 0.04878 | D32: kilogram | E32: biosphere3 | F32: air | H32: biosphere | I32: ecoinvent default data
A33: Heat, waste | C33: 1.28 | D33: megajoule | E33: biosphere3 | F33: air::non-urban air or from high stacks | H33: biosphere | I33: ecoinvent default data
A34: Sulfur dioxide | C34: 6.599e-06 | D34: kilogram | E34: biosphere3 | F34: air::non-urban air or from high stacks | H34: biosphere | I34: ecoinvent default data
A35: Hydrogen sulfide | C35: 6.7e-06 | D35: kilogram | E35: biosphere3 | F35: air::non-urban air or from high stacks | H35: biosphere | I35: ecoinvent default data
A37: Activity | B37: biogas upgrading to biomethane, pressure swing adsorption w/ CCS
A38: comment | B38: This dataset represents the upgrading of biogas to biomethane using the pressure swing adsorption (PSA) technology coupled with CCS. Due to the relatively highly concentrated CO2 generated from biogas upgrading, the process requires only additional gas compression and dehydratation
A39: location | B39: RER
A40: reference product | B40: biomethane, high pressure
A41: production amount | B41: 1
A42: unit | B42: cubic meter
A43: source | B43: Based on the equivalent dataset from ecoinvent v3.8. Electricity consumption was updated and the input volume of biogas and emissions of CH4 and CO2 were recalculated based on the carbon balance. The CO2 storage dataset available in premise was used
...

Sheet LCI_e-MeOH
A1: Activity | B1: methanol production, electrolytic H2 w/ wind, CO2 from DAC
A2: comment | B2: This dataset represents the production of methanol from electrolytic hydrogen and CO2 captured from the atmosphere
A3: location | B3: RER
A4: reference product | B4: methanol
A5: production amount | B5: 1
A6: unit | B6: kilogram
A7: source | B7: premise datasets for methanol synthesis and distillation
A8: Exchanges
A9: name | B9: reference product | C9: amount | D9: unit | E9: database | F9: categories | G9: location | H9: type | I9: comment
A10: methanol production, electrolytic H2 w/ wind, CO2 from DAC | B10: methanol | C10: 1 | D10: kilogram | E10: biogas to chemicals | G10: RER | H10: production
A11: carbon dioxide, captured from atmosphere, with heat pump heat, and grid electricity | B11: carbon dioxide, captured from the atmosphere | C11: 1.6904232 | D11: kilogram | E11: ecoinvent | G11: WEU | H11: technosphere | I11: premise default data for synthesis
A12: hydrogen production, gaseous, 25 bar, from electrolysis w/ wind | B12: hydrogen, gaseous, 25 bar | C12: 0.1389755 | D12: kilogram | E12: biogas to chemicals | G12: RER | H12: technosphere | I12: premise default data for synthesis
A13: market group for electricity, low voltage | B13: electricity, low voltage | C13: 0.30289532 | D13: kilowatt hour | E13: ecoinvent | G13: RER | H13: technosphere | I13: premise default data for synthesis
A14: steam production, as energy carrier, in chemical industry | B14: heat, from steam, in chemical industry | C14: 3.509803 | D14: megajoule | E14: ecoinvent | G14: RER | H14: technosphere | I14: premise default data for distillation
A15: methanol production facility, construction | B15: methanol production facility, construction | C15: =12.4568278943278+12.89 -> 25.346828 | D15: unit | E15: ecoinvent | G15: RER | H15: technosphere | I15: premise default data for distillation + synthesis
A16: market for tap water | B16: tap water | C16: 68.819599 | D16: kilogram | E16: ecoinvent | G16: Europe without Switzerland | H16: technosphere | I16: premise default data for synthesis
A17: market for zinc oxide | B17: zinc oxide | C17: 7.9287305e-06 | D17: kilogram | E17: ecoinvent | G17: GLO | H17: technosphere | I17: premise default data for synthesis
A18: market for copper oxide | B18: copper oxide | C18: 2.1135857e-05 | D18: kilogram | E18: ecoinvent | G18: GLO | H18: technosphere | I18: premise default data for synthesis
A19: market for aluminium oxide, metallurgical | B19: aluminium oxide, metallurgical | C19: 3.9643653e-06 | D19: kilogram | E19: ecoinvent | G19: IAI Area, EU27 & EFTA | H19: technosphere | I19: premise default data for synthesis
A20: treatment of wastewater, average, capacity 1E9l/year | B20: wastewater, average | C20: -0.068819599 | D20: cubic meter | E20: ecoinvent | G20: Europe without Switzerland | H20: technosphere | I20: premise default data for synthesis
A21: Carbon dioxide, fossil | C21: 0.13206759 | D21: kilogram | E21: biosphere3 | F21: air::non-urban air or from high stacks | H21: biosphere | I21: premise default data for distillation
A22: Carbon monoxide, fossil | C22: 1.6694063e-06 | D22: kilogram | E22: biosphere3 | F22: air::non-urban air or from high stacks | H22: biosphere | I22: premise default data for distillation
A24: Activity | B24: hydrogen production, gaseous, 25 bar, from electrolysis w/ wind
A25: comment | B25: This dataset represents the production of hydrogen from electrolysis with wind electricity
A26: location | B26: RER
A27: reference product | B27: hydrogen, gaseous, 25 bar
A28: production amount | B28: 1
A29: unit | B29: kilogram
A30: source | B30: premise dataset for hydrogen production by electrolysis
A31: Exchanges
A32: name | B32: reference product | C32: amount | D32: unit | E32: database | F32: categories | G32: location | H32: type | I32: comment
A33: hydrogen production, gaseous, 25 bar, from electrolysis w/ wind | B33: hydrogen, gaseous, 25 bar | C33: 1 | D33: kilogram | E33: biogas to chemicals | G33: RER | H33: production
A34: electricity production, wind, 1-3MW turbine, onshore | B34: electricity, high voltage | C34: 55.051 | D34: kilowatt hour | E34: ecoinvent | G34: RoW | H34: technosphere | I34: premise default data
A35: electrolyzer, PEM, Balance of Plant | B35: electrolyzer, PEM, Balance of Plant | C35: 3.2831536e-07 | D35: unit | E35: ecoinvent | G35: GLO | H35: technosphere | I35: premise default data
A36: electrolyzer, PEM, Stack | B36: electrolyzer, PEM, Stack | C36: 9.3804389e-07 | D36: unit | E36: ecoinvent | G36: GLO | H36: technosphere | I36: premise default data
A37: market for water, deionised | B37: water, deionised | C37: 12 | D37: kilogram | E37: ecoinvent | G37: Europe without Switzerland | H37: technosphere | I37: premise default data

Sheet LCI_Heat-NG-CCS
A1: Activity | B1: heat production, natural gas, at boiler condensing modulating >100kW w/ CCS
A2: comment | B2: This dataset represents the production of heat from natural gas at industrial furnace coupled with CCS
A3: location | B3: GLO
A4: reference product | B4: heat, district or industrial, natural gas
A5: production amount | B5: 1
A6: unit | B6: megajoule
A7: source | B7: Based on the equivalent dataset from ecoinvent v3.8. Emissions of CO2 were adjusted assuming 90% capture rate
A8: Exchanges
A9: name | B9: reference product | C9: amount | D9: unit | E9: database | F9: categories | G9: location | H9: type | I9: comment
A10: heat production, natural gas, at boiler condensing modulating >100kW w/ CCS | B10: heat, district or industrial, natural gas | C10: 1 | D10: megajoule | E10: biogas to chemicals | G10: GLO | H10: production
A11: market group for natural gas, high pressure | B11: natural gas, high pressure | C11: 0.027008048 | D11: cubic meter | E11: ecoinvent | G11: GLO | H11: technosphere | I11: ecoinvent default data; sum of all suppliers
A12: market group for electricity, low voltage | B12: electricity, low voltage | C12: 0.0010882353 | D12: kilowatt hour | E12: ecoinvent | G12: GLO | H12: technosphere | I12: ecoinvent default data
A13: market for industrial furnace, natural gas | B13: industrial furnace, natural gas | C13: 2.745098e-09 | D13: unit | E13: ecoinvent | G13: GLO | H13: technosphere | I13: ecoinvent default data
A14: carbon dioxide capture and storage, from natural gas boiler, 400 km pipeline, storage 3000m | B14: carbon dioxide capture and storage | C14: ='Carbon balance'!B39 -> 0.049411765 | D14: kilogram | E14: biogas to chemicals | G14: GLO | H14: technosphere | I14: assume 90% capture rate
A15: Carbon dioxide, fossil | C15: ='Carbon balance'!B40 -> 0.0054901961 | D15: kilogram | E15: biosphere3 | F15: air::urban air close to ground | H15: biosphere | I15: ecoinvent default data; modified to include 90% capture rate
A16: Methane, fossil | C16: 1.9607843e-06 | D16: kilogram | E16: biosphere3 | F16: air::urban air close to ground | H16: biosphere | I16: ecoinvent default data
A17: Pentane | C17: 1.1764706e-06 | D17: kilogram | E17: biosphere3 | F17: air::urban air close to ground | H17: biosphere | I17: ecoinvent default data
A18: Sulfate | C18: 4.9019608e-08 | D18: kilogram | E18: biosphere3 | F18: water::surface water | H18: biosphere | I18: ecoinvent default data
A19: Acetaldehyde | C19: 9.8039216e-10 | D19: kilogram | E19: biosphere3 | F19: air::urban air close to ground | H19: biosphere | I19: ecoinvent default data
A20: Sulfur dioxide | C20: 4.9019608e-07 | D20: kilogram | E20: biosphere3 | F20: air::urban air close to ground | H20: biosphere | I20: ecoinvent default data
A21: Carbon monoxide, fossil | C21: 2.8431373e-06 | D21: kilogram | E21: biosphere3 | F21: air::urban air close to ground | H21: biosphere | I21: ecoinvent default data
A22: Nitrate | C22: 1.2745098e-07 | D22: kilogram | E22: biosphere3 | F22: water::surface water | H22: biosphere | I22: ecoinvent default data
A23: Mercury | C23: 2.9411765e-11 | D23: kilogram | E23: biosphere3 | F23: air::urban air close to ground | H23: biosphere | I23: ecoinvent default data
A24: Propane | C24: 1.9607843e-07 | D24: kilogram | E24: biosphere3 | F24: air::urban air close to ground | H24: biosphere | I24: ecoinvent default data
A25: Sulfite | C25: 4.9019608e-08 | D25: kilogram | E25: biosphere3 | F25: water::surface water | H25: biosphere | I25: ecoinvent default data
A26: Particulates, < 2.5 um | C26: 9.8039216e-08 | D26: kilogram | E26: biosphere3 | F26: air::urban air close to ground | H26: biosphere | I26: ecoinvent default data
A27: Acetic acid | C27: 1.4705882e-07 | D27: kilogram | E27: biosphere3 | F27: air::urban air close to ground | H27: biosphere | I27: ecoinvent default data
... A38: Butane | C38: 6.8627451e-07 | D38: kilogram | E38: biosphere3 | F38: air::urban air close to ground | H38: biosphere | I38: ecoinvent default data
A40: Activity | B40: carbon dioxide capture and storage, from natural gas boiler, 400 km pipeline, storage 3000m
A41: comment | B41: This dataset represents the post-combustion capture of 1 kg CO2 from natural gas boiler. The process is defined for chemical absorption usin MEA
A42: location | B42: GLO
A43: reference product | B43: carbon dioxide capture and storage
A44: production amount | B44: 1
A45: unit | B45: kilogram
A46: source | B46: Based on the premise dataset 'CO2 capture/natural gas, post, 400km pipeline, storage 3000m'. Dataset uses data from Volkart et al. 2013
A47: Exchanges
A48: name | B48: reference product | C48: amount | D48: unit | E48: database | F48: categories | G48: location | H48: type | I48: comment
A49: carbon dioxide capture and storage, from natural gas boiler, 400 km pipeline, storage 3000m | B49: carbon dioxide capture and storage | C49: 1 | D49: kilogram | E49: biogas to chemicals | G49: GLO | H49: production
A50: CO2 storage/natural gas, post, 400km pipeline, storage 3000m | B50: CO2 storage/natural gas, post, 400km pipeline, storage 3000m | C50: 1 | D50: kilogram | E50: ecoinvent | G50: World | H50: technosphere | I50: premise dataset; 1 kg CO2 stored per kg of CO2 captured
A51: market group for electricity, low voltage | B51: electricity, low voltage | C51: 0.384 | D51: kilowatt hour | E51: ecoinvent | G51: GLO | H51: technosphere | I51: original dataset used electricity from the natural gas power plant where CO2 is captured; boilers need external electricity supply for CO2 capture
...

Sheet LCI_Heat-Biomethane
A1: skip
A2: name | B2: reference product | C2: database | D2: categories | E2: location | F2: type | G2: unit | H2: BAU, biomethane from PSA | I2: BAU, biomethane from PSA w/ CCS | J2: w/ CCS, biomethane from PSA | K2: w/ CCS, biomethane from PSA w/ CCS | L2: comment
A3: heat production, biomethane, at boiler condensing modulating <100kW | B3: heat, central or small-scale, biomethane | C3: biogas to chemicals | E3: RER | F3: production | G3: megajoule | H3: 1 | I3: 1 | J3: 1 | K3: 1
A4: biogas upgrading to biomethane, pressure swing adsorption | B4: biomethane, high pressure | C4: biogas to chemicals | E4: RER | F4: technosphere | G4: cubic meter | H4: ='Carbon balance'!$B$32 -> 0.028837662 | J4: ='Carbon balance'!$B$32 -> 0.028837662 | L4: assume boiler efficiency and the characteristics of the biomethane; see Carbon balance
A5: biogas upgrading to biomethane, pressure swing adsorption w/ CCS | B5: biomethane, high pressure | C5: biogas to chemicals | E5: RER | F5: technosphere | G5: cubic meter | I5: ='Carbon balance'!$B$32 -> 0.028837662 | K5: ='Carbon balance'!$B$32 -> 0.028837662 | L5: assume boiler efficiency and the characteristics of the biomethane; see Carbon balance
A6: market group for electricity, low voltage | B6: electricity, low voltage | C6: ecoinvent | E6: RER | F6: technosphere | G6: kilowatt hour | H6: 0.0027244 | I6: 0.0027244 | J6: 0.0027244 | K6: 0.0027244 | L6: ecoinvent default data
A7: market for gas boiler | B7: gas boiler | C7: ecoinvent | E7: GLO | F7: technosphere | G7: unit | H7: 6.468e-07 | I7: 6.468e-07 | J7: 6.468e-07 | K7: 6.468e-07 | L7: ecoinvent default data
A8: carbon dioxide capture and storage, from biomethane boiler, 400 km pipeline, storage 3000m | B8: CO2 storage/natural gas, post, 200km pipeline, storage 1000m | C8: ecoinvent | E8: WEU | F8: kilogram | J8: ='Carbon balance'!$B$44 -> 0.051182686 | K8: ='Carbon balance'!$B$44 -> 0.051182686 | L8: assume 90% capture rate
A9: Carbon dioxide, non-fossil | C9: biosphere3 | D9: air::non-urban air or from high stacks | F9: biosphere | G9: kilogram | H9: ='Carbon balance'!$B$42 -> 0.056869651 | I9: ='Carbon balance'!$B$42 -> 0.056869651 | J9: ='Carbon balance'!$B$45 -> 0.0056869651 | K9: ='Carbon balance'!$B$45 -> 0.0056869651 | L9: calculated based on the CO2 content of the biomethane plus the CH4 content that is oxidized to CO2
A10: Methane, non-fossil | C10: biosphere3 | D10: air::non-urban air or from high stacks | F10: biosphere | G10: kilogram | H10: ='Carbon balance'!$B$43 -> 2.8260909e-06 | I10: ='Carbon balance'!$B$43 -> 2.8260909e-06 | J10: ='Carbon balance'!$B$43 -> 2.8260909e-06 | K10: ='Carbon balance'!$B$43 -> 2.8260909e-06 | L10: calculated based on the CH4 content of the biomethane and assuming 99.99% oxidation efficiency of boiler
A11: Nitrate | C11: biosphere3 | D11: water::surface water | F11: biosphere | G11: kilogram | H11: 1.274e-07 | I11: 1.274e-07 | J11: 1.274e-07 | K11: 1.274e-07 | L11: ecoinvent default data
A12: Benzo(a)pyrene | C12: biosphere3 | D12: air::non-urban air or from high stacks | F12: biosphere | G12: kilogram | H12: 9.8e-12 | I12: 9.8e-12 | J12: 9.8e-12 | K12: 9.8e-12 | L12: ecoinvent default data
A13: Nitrite | C13: biosphere3 | D13: water::surface water | F13: biosphere | G13: kilogram | H13: 2.94e-09 | I13: 2.94e-09 | J13: 2.94e-09 | K13: 2.94e-09 | L13: ecoinvent default data
A14: Sulfur dioxide | C14: biosphere3 | D14: air::non-urban air or from high stacks | F14: biosphere | G14: kilogram | H14: 4.9e-07 | I14: 4.9e-07 | J14: 4.9e-07 | K14: 4.9e-07 | L14: ecoinvent default data
A15: Benzene | C15: biosphere3 | D15: air::non-urban air or from high stacks | F15: biosphere | G15: kilogram | H15: 3.92e-07 | I15: 3.92e-07 | J15: 3.92e-07 | K15: 3.92e-07 | L15: ecoinvent default data
A16: Sulfate | C16: biosphere3 | D16: water::surface water | F16: biosphere | G16: kilogram | H16: 4.9e-08 | I16: 4.9e-08 | J16: 4.9e-08 | K16: 4.9e-08 | L16: ecoinvent default data
A17: Propionic acid | C17: biosphere3 | D17: air::non-urban air or from high stacks | F17: biosphere | G17: kilogram | H17: 1.96e-08 | I17: 1.96e-08 | J17: 1.96e-08 | K17: 1.96e-08 | L17: ecoinvent default data
A18: Toluene | C18: biosphere3 | D18: air::non-urban air or from high stacks | F18: biosphere | G18: kilogram | H18: 1.96e-07 | I18: 1.96e-07 | J18: 1.96e-07 | K18: 1.96e-07 | L18: ecoinvent default data
A19: Carbon monoxide, non-fossil | C19: biosphere3 | D19: air::non-urban air or from high stacks | F19: biosphere | G19: kilogram | H19: 5.782e-06 | I19: 5.782e-06 | J19: 5.782e-06 | K19: 5.782e-06 | L19: ecoinvent default data
A20: Particulates, < 2.5 um | C20: biosphere3 | D20: air::non-urban air or from high stacks | F20: biosphere | G20: kilogram | H20: 9.8e-08 | I20: 9.8e-08 | J20: 9.8e-08 | K20: 9.8e-08 | L20: ecoinvent default data
A21: Sulfite | C21: biosphere3 | D21: water::surface water | F21: biosphere | G21: kilogram | H21: 4.9e-08 | I21: 4.9e-08 | J21: 4.9e-08 | K21: 4.9e-08 | L21: ecoinvent default data
A22: Dinitrogen monoxide | C22: biosphere3 | D22: air::non-urban air or from high stacks | F22: biosphere | G22: kilogram | H22: 4.9e-07 | I22: 4.9e-07 | J22: 4.9e-07 | K22: 4.9e-07 | L22: ecoinvent default data
... A32: Butane | C32: biosphere3 | D32: air::non-urban air or from high stacks | F32: biosphere | G32: kilogram | H32: 6.86e-07 | I32: 6.86e-07 | J32: 6.86e-07 | K32: 6.86e-07 | L32: ecoinvent default data

Sheet LCI_MeOH
A1: skip
A2: name | B2: reference product | C2: database | D2: categories | E2: location | F2: type | G2: unit | H2: w/ CCS, natural gas | I2: BAU, biomethane from PSA | J2: BAU, biomethane from PSA w/ CCS | K2: w/ CCS, biomethane from PSA | L2: w/ CCS, biomethane from PSA w/ CCS | M2: comment
A3: methanol production | B3: methanol | C3: biogas to chemicals | E3: GLO | F3: production | G3: kilogram | H3: 1
A4: methanol production | B4: methanol | C4: biogas to chemicals | E4: RER | F4: production | G4: kilogram | I4: 1 | J4: 1 | K4: 1 | L4: 1
A5: market group for natural gas, high pressure | B5: natural gas, high pressure | C5: ecoinvent | E5: GLO | F5: technosphere | G5: cubic meter | H5: 0.65179487 | M5: ecoinvent default data
A6: biogas upgrading to biomethane, pressure swing adsorption | B6: biomethane, high pressure | C6: biogas to chemicals | E6: RER | F6: technosphere | G6: cubic meter | I6: 0.65179487 | K6: 0.65179487 | M6: ecoinvent default data
A7: biogas upgrading to biomethane, pressure swing adsorption w/ CCS | B7: biomethane, high pressure | C7: biogas to chemicals | E7: RER | F7: technosphere | G7: cubic meter | J7: 0.65179487 | L7: 0.65179487 | M7: ecoinvent default data
A8: heat production, natural gas, at boiler condensing modulating >100kW w/ CCS | B8: heat, district or industrial, natural gas | C8: biogas to chemicals | E8: GLO | F8: technosphere | G8: megajoule | H8: 6.93 | M8: ecoinvent default data
A9: heat production, biomethane, at boiler condensing modulating <100kW BAU, biomethane from PSA | B9: heat, central or small-scale, biomethane | C9: biogas to chemicals | E9: RER | F9: technosphere | G9: megajoule | I9: 6.93 | M9: ecoinvent default data
A10: heat production, biomethane, at boiler condensing modulating <100kW BAU, biomethane from PSA w/ CCS | B10: heat, central or small-scale, biomethane | C10: biogas to chemicals | E10: RER | F10: technosphere | G10: megajoule | J10: 6.93 | M10: ecoinvent default data
A11: heat production, biomethane, at boiler condensing modulating <100kW w/ CCS, biomethane from PSA | B11: heat, central or small-scale, biomethane | C11: biogas to chemicals | E11: RER | F11: technosphere | G11: megajoule | K11: 6.93 | M11: ecoinvent default data
A12: heat production, biomethane, at boiler condensing modulating <100kW w/ CCS, biomethane from PSA w/ CCS | B12: heat, central or small-scale, biomethane | C12: biogas to chemicals | E12: RER | F12: technosphere | G12: megajoule | L12: 6.93 | M12: ecoinvent default data
A13: market group for electricity, medium voltage | B13: electricity, medium voltage | C13: ecoinvent | E13: GLO | F13: technosphere | G13: kilowatt hour | H13: 0.074 | M13: ecoinvent default data
A14: market group for electricity, medium voltage | B14: electricity, medium voltage | C14: ecoinvent | E14: RER | F14: technosphere | G14: kilowatt hour | I14: 0.074 | J14: 0.074 | K14: 0.074 | L14: 0.074 | M14: ecoinvent default data
A15: market for zinc | B15: zinc | C15: ecoinvent | E15: GLO | F15: technosphere | G15: kilogram | H15: 3e-05 | I15: 3e-05 | J15: 3e-05 | K15: 3e-05 | L15: 3e-05 | M15: ecoinvent default data
A16: market for molybdenum | B16: molybdenum | C16: ecoinvent | E16: GLO | F16: technosphere | G16: kilogram | H16: 1e-05 | I16: 1e-05 | J16: 1e-05 | K16: 1e-05 | L16: 1e-05 | M16: ecoinvent default data
A17: market for copper oxide | B17: copper oxide | C17: ecoinvent | E17: GLO | F17: technosphere | G17: kilogram | H17: 9e-05 | I17: 9e-05 | J17: 9e-05 | K17: 9e-05 | L17: 9e-05 | M17: ecoinvent default data
A18: market for methanol factory | B18: methanol factory | C18: ecoinvent | E18: GLO | F18: technosphere | G18: unit | H18: 3.72e-11 | I18: 3.72e-11 | J18: 3.72e-11 | K18: 3.72e-11 | L18: 3.72e-11 | M18: ecoinvent default data
A19: market for nickel, class 1 | B19: nickel, class 1 | C19: ecoinvent | E19: GLO | F19: technosphere | G19: kilogram | H19: 2e-05 | I19: 2e-05 | J19: 2e-05 | K19: 2e-05 | L19: 2e-05 | M19: ecoinvent default data
A20: market for water, deionised | B20: water, deionised | C20: ecoinvent | E20: Europe without Switzerland | F20: technosphere | G20: kilogram | H20: 0.20000395 | I20: =SUM($H$20:$H$22) -> 0.85 | J20: =SUM($H$20:$H$22) -> 0.85 | K20: =SUM($H$20:$H$22) -> 0.85 | L20: =SUM($H$20:$H$22) -> 0.85 | M20: ecoinvent default data
A21: market for water, deionised | B21: water, deionised | C21: ecoinvent | E21: CH | F21: technosphere | G21: kilogram | H21: 0.00071996494 | M21: ecoinvent default data
A22: market for water, deionised | B22: water, deionised | C22: ecoinvent | E22: RoW | F22: technosphere | G22: kilogram | H22: 0.64927608 | M22: ecoinvent default data
A23: market for aluminium oxide, non-metallurgical | B23: aluminium oxide, non-metallurgical | C23: ecoinvent | E23: RoW | F23: technosphere | G23: kilogram | H23: 0.0002052511 | M23: ecoinvent default data
A24: market for aluminium oxide, non-metallurgical | B24: aluminium oxide, non-metallurgical | C24: ecoinvent | E24: IAI Area, EU27 & EFTA | F24: technosphere | G24: kilogram | H24: 3.4748895e-05 | I24: =SUM($H$23:$H$24) -> 0.00024 | J24: =SUM($H$23:$H$24) -> 0.00024 | K24: =SUM($H$23:$H$24) -> 0.00024 | L24: =SUM($H$23:$H$24) -> 0.00024 | M24: ecoinvent default data
A25: Methane, fossil | C25: biosphere3 | D25: air::non-urban air or from high stacks | F25: biosphere | G25: kilogram | H25: 0.00098 | M25: ecoinvent default data
A26: Methane, non-fossil | C26: biosphere3 | D26: air::non-urban air or from high stacks | F26: biosphere | G26: kilogram | I26: 0.00098 | J26: 0.00098 | K26: 0.00098 | L26: 0.00098 | M26: ecoinvent default data
A27: Water, cooling, unspecified natural origin | C27: biosphere3 | D27: natural resource::in water | F27: biosphere | G27: cubic meter | H27: 0.00816 | I27: 0.00816 | J27: 0.00816 | K27: 0.00816 | L27: 0.00816 | M27: ecoinvent default data
A28: Chloride | C28: biosphere3 | D28: water | F28: biosphere | G28: kilogram | H28: 2e-06 | I28: 2e-06 | J28: 2e-06 | K28: 2e-06 | L28: 2e-06 | M28: ecoinvent default data
A29: Nitrogen oxides | C29: biosphere3 | D29: air::non-urban air or from high stacks | F29: biosphere | G29: kilogram | H29: 0.00015 | I29: 0.00015 | J29: 0.00015 | K29: 0.00015 | L29: 0.00015 | M29: ecoinvent default data
A30: Water | C30: biosphere3 | D30: water | F30: biosphere | G30: cubic meter | H30: 0.00567375 | I30: 0.00567375 | J30: 0.00567375 | K30: 0.00567375 | L30: 0.00567375 | M30: ecoinvent default data
A31: BOD5, Biological Oxygen Demand | C31: biosphere3 | D31: water | F31: biosphere | G31: kilogram | H31: 0.00018 | I31: 0.00018 | J31: 0.00018 | K31: 0.00018 | L31: 0.00018 | M31: ecoinvent default data
A32: Methanol | C32: biosphere3 | D32: water | F32: biosphere | G32: kilogram | H32: 3e-05 | I32: 3e-05 | J32: 3e-05 | K32: 3e-05 | L32: 3e-05 | M32: ecoinvent default data
A33: TOC, Total Organic Carbon | C33: biosphere3 | D33: water | F33: biosphere | G33: kilogram | H33: 0.00024 | I33: 0.00024 | J33: 0.00024 | K33: 0.00024 | L33: 0.00024 | M33: ecoinvent default data
A34: AOX, Adsorbable Organic Halogen as Cl | C34: biosphere3 | D34: water | F34: biosphere | G34: kilogram | H34: 1e-06 | I34: 1e-06 | J34: 1e-06 | K34: 1e-06 | L34: 1e-06 | M34: ecoinvent default data
A35: Methanol | C35: biosphere3 | D35: air::non-urban air or from high stacks | F35: biosphere | G35: kilogram | H35: 0.00053 | I35: 0.00053 | J35: 0.00053 | K35: 0.00053 | L35: 0.00053 | M35: ecoinvent default data
A36: Water | C36: biosphere3 | D36: air | F36: biosphere | G36: cubic meter | H36: 0.00333625 | I36: 0.00333625 | J36: 0.00333625 | K36: 0.00333625 | L36: 0.00333625 | M36: ecoinvent default data
A37: Suspended solids, unspecified | C37: biosphere3 | D37: water | F37: biosphere | G37: kilogram | H37: 2e-05 | I37: 2e-05 | J37: 2e-05 | K37: 2e-05 | L37: 2e-05 | M37: ecoinvent default data
A38: DOC, Dissolved Organic Carbon | C38: biosphere3 | D38: water | F38: biosphere | G38: kilogram | H38: 0.00024 | I38: 0.00024 | J38: 0.00024 | K38: 0.00024 | L38: 0.00024 | M38: ecoinvent default data
... A43: Phenol | C43: biosphere3 | D43: water | F43: biosphere | G43: kilogram | H43: 1e-05 | I43: 1e-05 | J43: 1e-05 | K43: 1e-05 | L43: 1e-05 | M43: ecoinvent default data

Sheet LCI_MTO_MTA
A1: skip
A2: name | B2: reference product | C2: database | D2: categories | E2: location | F2: type | G2: unit | H2: MTE, methanol w/ CCS, natural gas | I2: MTE, methanol, H2 from wind, CO2 from DAC | J2: MTE, methanol BAU, biomethane from PSA | K2: MTE, methanol BAU, biomethane from PSA w/ CCS | L2: MTE, methanol w/ CCS, biomethane from PSA | M2: MTE, methanol w/ CCS, biomethane from PSA w/ CCS | N2: MTP, methanol w/ CCS, natural gas | O2: MTP, methanol, H2 from wind, CO2 from DAC | P2: MTP, methanol BAU, biomethane from PSA | Q2: MTP, methanol BAU, biomethane from PSA w/ CCS | R2: MTP, methanol w/ CCS, biomethane from PSA | S2: MTP, methanol w/ CCS, biomethane from PSA w/ CCS | T2: MTB, methanol w/ CCS, natural gas | U2: MTB, methanol, H2 from wind, CO2 from DAC | V2: MTB, methanol BAU, biomethane from PSA | W2: MTB, methanol BAU, biomethane from PSA w/ CCS | X2: MTB, methanol w/ CCS, biomethane from PSA | Y2: MTB, methanol w/ CCS, biomethane from PSA w/ CCS | Z2: MTT, methanol w/ CCS, natural gas | AA2: MTT, methanol, H2 from wind, CO2 from DAC | AB2: MTT, methanol BAU, biomethane from PSA | AC2: MTT, methanol BAU, biomethane from PSA w/ CCS | AD2: MTT, methanol w/ CCS, biomethane from PSA | AE2: MTT, methanol w/ CCS, biomethane from PSA w/ CCS | AF2: MTX, methanol w/ CCS, natural gas | AG2: MTX, methanol, H2 from wind, CO2 from DAC | AH2: MTX, methanol BAU, biomethane from PSA | AI2: MTX, methanol BAU, biomethane from PSA w/ CCS | AJ2: MTX, methanol w/ CCS, biomethane from PSA | AK2: MTX, methanol w/ CCS, biomethane from PSA w/ CCS
A3: ethylene production, methanol-to-olefins | B3: ethylene | C3: biogas to chemicals | E3: RER | F3: production | G3: kilogram | H3: 1 | I3: 1 | J3: 1 | K3: 1 | L3: 1 | M3: 1
A4: propylene production, methanol-to-olefins | B4: propylene | C4: biogas to chemicals | E4: RER | F4: production | G4: kilogram | N4: 1 | O4: 1 | P4: 1 | Q4: 1 | R4: 1 | S4: 1
A5: benzene production, methanol-to-aromatics | B5: benzene | C5: biogas to chemicals | E5: RER | F5: production | G5: kilogram | T5: 1 | U5: 1 | V5: 1 | W5: 1 | X5: 1 | Y5: 1
A6: toluene production, methanol-to-aromatics | B6: toluene | C6: biogas to chemicals | E6: RER | F6: production | G6: kilogram | Z6: 1 | AA6: 1 | AB6: 1 | AC6: 1 | AD6: 1 | AE6: 1
A7: xylenes production, methanol-to-aromatics | B7: xylenes | C7: biogas to chemicals | E7: RER | F7: production | G7: kilogram | AF7: 1 | AG7: 1 | AH7: 1 | AI7: 1 | AJ7: 1 | AK7: 1
A8: methanol production w/ CCS, natural gas | B8: methanol | C8: biogas to chemicals | E8: GLO | F8: technosphere | G8: kilogram | H8: 2.48 | N8: 2.3 | T8: 2.56 | Z8: 2.9 | AF8: 3.11
A9: methanol production, electrolytic H2 w/ wind, CO2 from DAC | B9: methanol | C9: biogas to chemicals | E9: RER | F9: technosphere | G9: kilogram | I9: 2.48 | O9: 2.3 | U9: 2.56 | AA9: 2.9 | AG9: 3.11
A10: methanol production BAU, biomethane from PSA | B10: methanol | C10: biogas to chemicals | E10: RER | F10: technosphere | G10: kilogram | J10: 2.48 | P10: 2.3 | V10: 2.56 | AB10: 2.9 | AH10: 3.11
A11: methanol production BAU, biomethane from PSA w/ CCS | B11: methanol | C11: biogas to chemicals | E11: RER | F11: technosphere | G11: kilogram | K11: 2.48 | Q11: 2.3 | W11: 2.56 | AC11: 2.9 | AI11: 3.11
A12: methanol production w/ CCS, biomethane from PSA | B12: methanol | C12: biogas to chemicals | E12: RER | F12: technosphere | G12: kilogram | L12: 2.48 | R12: 2.3 | X12: 2.56 | AD12: 2.9 | AJ12: 3.11
A13: methanol production w/ CCS, biomethane from PSA w/ CCS | B13: methanol | C13: biogas to chemicals | E13: RER | F13: technosphere | G13: kilogram | M13: 2.48 | S13: 2.3 | Y13: 2.56 | AE13: 2.9 | AK13: 3.11
A14: market group for electricity, medium voltage | B14: electricity, medium voltage | C14: ecoinvent | E14: RER | F14: technosphere | G14: kilowatt hour | H14: 1.12 | I14: 1.12 | J14: 1.12 | K14: 1.12 | L14: 1.12 | M14: 1.12 | N14: 1.04 | O14: 1.04 | P14: 1.04 | Q14: 1.04 | R14: 1.04 | S14: 1.04 | T14: 0.29 | U14: 0.29 | V14: 0.29 | W14: 0.29 | X14: 0.29 | Y14: 0.29 | Z14: 0.33 | AA14: 0.33 | AB14: 0.33 | AC14: 0.33 | AD14: 0.33 | AE14: 0.33 | AF14: 0.35 | AG14: 0.35 | AH14: 0.35 | AI14: 0.35 | AJ14: 0.35 | AK14: 0.35
A15: market for heat, from steam, in chemical industry | B15: heat, from steam, in chemical industry | C15: ecoinvent | E15: RER | F15: technosphere | G15: megajoule | H15: 0.59 | I15: 0.59 | J15: 0.59 | K15: 0.59 | L15: 0.59 | M15: 0.59 | N15: 0.54 | O15: 0.54 | P15: 0.54 | Q15: 0.54 | R15: 0.54 | S15: 0.54 | T15: 2.35 | U15: 2.35 | V15: 2.35 | W15: 2.35 | X15: 2.35 | Y15: 2.35 | Z15: 2.66 | AA15: 2.66 | AB15: 2.66 | AC15: 2.66 | AD15: 2.66 | AE15: 2.66 | AF15: 2.85 | AG15: 2.85 | AH15: 2.85 | AI15: 2.85 | AJ15: 2.85 | AK15: 2.85

Sheet Carbon balance
A1: skip
B2: Animal manure | C2: Biowaste | D2: Crop residues | E2: Sewage sludge | F2: Sequential cropping
G3: Mass (kg) | H3: Density gas (kg/Nm3) | I3: LHV (MJ/m3) | J3: LHV (MJ/kg)
A4: Biogas | B4: 1 | C4: 1 | D4: 1 | E4: 1 | F4: 1 | G4: =D5*H5+D6*H6 -> 1.229 | H4: =D5*H5+D6*H6 -> 1.229 | I4: =D5*I5 -> 21.48 | J4: =I4/H4 -> 17.477624
A5: CH4 | B5: 0.6 | C5: 0.6 | D5: 0.6 | E5: 0.6 | F5: 0.6 | G5: =D5*H5 -> 0.4302 | H5: 0.717 | I5: 35.8 | J5: 50 | K5: density at 0ºC and 1 atm | L5: https://www.engineeringtoolbox.com/gas-density-d_158.html
A6: CO2 | B6: 0.4 | C6: 0.4 | D6: 0.4 | E6: 0.4 | F6: 0.4 | G6: =D6*H6 -> 0.7988 | H6: 1.997 | I6: - | J6: - | K6: density at 0ºC and 1 atm | L6: https://www.engineeringtoolbox.com/gas-density-d_158.html
A7: Natural gas | I7: 36.6 | L7: https://www.engineeringtoolbox.com/gas-density-d_158.html
G8: Units
A9: Carbon content biogas | B9: =((B5*$H$5*12/16)+(B6*$H$6*12/44)) -> 0.54050455 | C9: =((C5*$H$5*12/16)+(C6*$H$6*12/44)) -> 0.54050455 | D9: =((D5*$H$5*12/16)+(D6*$H$6*12/44)) -> 0.54050455 | E9: =((E5*$H$5*12/16)+(E6*$H$6*12/44)) -> 0.54050455 | F9: =((F5*$H$5*12/16)+(F6*$H$6*12/44)) -> 0.54050455 | G9: kg C/m3 biogas
A10: CO2 uptake | B10: =B9*44/12 -> 1.98185 | C10: =C9*44/12 -> 1.98185 | D10: =D9*44/12 -> 1.98185 | E10: =E9*44/12 -> 1.98185 | F10: =F9*44/12 -> 1.98185 | G10: kg CO2/m3 biogas
A17: Biomethane upgrading balance | B17: Amount | G17: Units
A18: Upgrading leakage | B18: 0.02 | G18: % CH4
A19: Biomethane purity | B19: 0.98 | G19: % CH4 (v/v)
A20: Biogas input | B20: =B19/D5*(1+B18) -> 1.666 | G20: Nm3/Nm3 biomethane
A21: Leakage of CH4 | B21: =(B20*D5*B18)*H5 -> 0.014334264 | G21: kg CH4/m3 biomethane
A22: Emissions of CO2 | B22: =B20*D6*B19*H6 -> 1.3041848 | G22: kg CO2/m3 biomethane
A23: Emissions of CO2 post CCS | B23: =B22*B18 -> 0.026083696 | G23: kg CO2/m3 biomethane
A24: CCS of CO2 | B24: =B22*(1-B18) -> 1.2781011 | G24: kg CO2/m3 biomethane
A25: Density biomethane | B25: =B19*H5+(1-B19)*H6 -> 0.7426 | G25: kg/Nm3 biomethane
A26: LHV of biomethane | B26: =B19*I5 -> 35.084 | G26: MJ/Nm3 biomethane
A27: LHV of biomethane | B27: =B26/B25 -> 47.244816 | G27: MJ/kg biomethane
A28: Heat production from biomethane combustion | B28: Amount | G28: Units
A29: Boiler efficiency | B29: ='LCI_Heat-NG-CCS'!C11*'Carbon balance'!I7 -> 0.98849456 | C29: *calculated from the natural gas boiler dataset | G29: MJheat/MJfuel
A30: Oxidation efficiency | B30: 0.9999 | G30: % CH4
A31: Heat production | B31: =B19*I5*B29*B30 -> 34.676875 | G31: MJheat/Nm3 biomethane
A32: Biomethane requirement | B32: =1/B31 -> 0.028837662 | G32: Nm3 biomethane/MJheat
A35: CO2 capture from boilers | B35: Amount | G35: Units
A36: Capture efficiency | B36: 0.9 | G36: % CO2
A37: Natural gas boiler
A38: Emissions of CO2 | B38: 0.054901961 | C38: *ecoinvent default data | G38: kg CO2/MJheat
A39: Capture of CO2 | B39: =B38*B36 -> 0.049411765 | G39: kg CO2/MJheat
A40: Emissions of CO2 after CCS | B40: =B38*(1-B36) -> 0.0054901961 | G40: kg CO2/MJheat
A41: Biomethane boiler
A42: Emissions of CO2 | B42: =(B32*(1-B19)*H6)+(B32*B19*B30*H5*44/16) -> 0.056869651 | C42: sum of CO2 content of the biomethane plus the CH4 content oxidized to CO2 | G42: kg CO2/MJheat
A43: Emissions of CH4 | B43: =B32*B19*(1-B30) -> 2.8260909e-06 | G43: kg CH4/MJheat
A44: Capture of CO2 | B44: =B42*B36 -> 0.051182686 | G44: kg CO2/MJheat
A45: Emissions of CO2 after CCS | B45: =B42*(1-B36) -> 0.0056869651 | G45: kg CO2/MJheat

Sheet LCI_Prospective_Foreground
A1: skip
A2: Prospective parameters
A3: process | B3: parameter
A4: biogas upgrading to biomethane | B4: electricity consumption
B5: leakage rate
A6: heat for steam reforming | B6: boiler efficiency?
A7: heat for steam reforming with CCS | B7: boiler efficiency?
B8: CO2 capture efficiency?
B9: electricity consumption
