Workbook

Sheet Aspen data
A1: Propanol (99.7 %wt)
B3: M. Wt. | C3: kmol/hr | D3: kg/hr | E3: kg/kg of propanol | F3: Type | G3: Molar ratio | H3: Stoichiometric ratio
A4: Carbon dioxide | B4: 44 | C4: =D4/B4 -> 2000 | D4: =0.704*10^9/8000 -> 88000 | E4: =D4/$D$8 -> 0.84717282 | F4: Feed | G4: =C4/$C$8 -> 1.1552357 | H4: 1
A5: Hydrogen | B5: 2 | C5: =D5/B5 -> 5562.5 | D5: =0.089*10^9/8000 -> 11125 | E5: =D5/$D$8 -> 0.10709997 | F5: Feed | G5: =C5/$C$8 -> 3.2129992 | H5: 3
A6: Ethylene | B6: 28 | C6: =D6/B6 -> 2008.9286 | D6: =0.45*10^9/8000 -> 56250 | E6: =D6/$D$8 -> 0.54151671 | F6: Feed | G6: =C6/$C$8 -> 1.160393 | H6: 1
A7: Carbon dioxide | B7: 44 | C7: =D7/B7 -> 823.86364 | D7: =0.29*10^9/8000 -> 36250 | E7: =D7/$D$8 -> 0.34897744 | F7: Emissions
A8: Propanol | B8: 60 | C8: 1731.2485 | D8: =B8*C8 -> 103874.91 | E8: =D8/$D$8 -> 1 | F8: Output
A10: Electricity | B10: =353 -> 353 | C10: TJ/a | E10: Cooling water | F10: 50797893 | J10: Data from mail
B11: =B10/8000 -> 0.044125 | C11: TJ/hr | F11: 16353215 | J11: Cooler 1: 50,797,892.70 | K11: Cooler 1: 74.63 to 45 (cooling water 35 to 40)
B12: =B11*10^12 -> 44125000000 | C12: Ws/hr | F12: 14308128 | J12: Cooler 2: 16,353,214.85 | K12: Cooler 2: 113.8 to 45 (cooling water 35 to 40)
B13: =B12/1000/3600 -> 12256.944 | C13: kWh/hr | F13: 12886015 | J13: Cooler 3: 14,308,128.36 | K13: Cooler 3: 115.8 to 45 (cooling water 35 to 40)
B14: =B13/$D$8 -> 0.11799716 | C14: kWh/kg propanol | F14: 12759030 | J14: Cooler 4: 12,886,014.83 | K14: Cooler 4: 117 to 45 (cooling water 35 to 40)
F15: 65294.12 | J15: Cooler 5: 12,759,029.65 | K15: Cooler 5: 112.6 to 45 (cooling water 35 to 40)
A16: Total cooling | B16: =F22+F27+F32 -> 5153.3233 | C16: TJ/a | F16: 2.3676637e+08 | J16: TEG regenerator cooler: 65,294.12 | K16: TEG regenerator cooler: maintain the temperature at 101.7 (cooling water 35 to 40)
F17: 56170876 | J17: HFM reactor cooler: 236,766,366.64 | K17: HFM reactor cooler: maintain the temperature at 100 (cooling water 35 to 40)
F18: 1.2527045e+08 | J18: Cooler 6: 56,170,876.50 | K18: Cooler 6: 100 to 45 (cooling water 35 to 40)
F19: 46320514 | J19: Cooler 7: 19,726,067.94 | K19: Cooler 7: 45 to 5 (ammonia refrigerant -36.71 to -7.673)
E20: Total | F20: =SUM(F10:F19) -> 5.7169778e+08 | G20: kJ/hr | J20: Distillation condenser: 52,741,568.80 | K20: Distillation condenser: maintain the temperature at 19.24 (chilled water 10 to 15)
F21: =F20/1000/$D$8 -> 5.5037139 | G21: MJ/kg propanol | J21: Hydrogenation reactor cooler: 125,270,450.40 | K21: Hydrogenation reactor cooler: maintain the temperature at 175 (cooling water 35 to 40)
F22: =F20/10^9*8000 -> 4573.5823 | G22: TJ/a | J22: Product cooler: 46,320,513.66 | K22: Product cooler: 97.15 to 45 (cooling water 35 to 40)
E24: Chilled water | F24: 52741569
E25: Total | F25: =SUM(F24:F24) -> 52741569 | G25: kJ/hr
F26: =F25/1000/$D$8 -> 0.50774117 | G26: MJ/kg propanol
F27: =F25/10^9*8000 -> 421.93255 | G27: TJ/a
E29: Ammonia | F29: 19726068
E30: Total | F30: =SUM(F29:F29) -> 19726068 | G30: kJ/hr
F31: =F30/1000/$D$8 -> 0.18990214 | G31: MJ/kg propanol
F32: =F30/10^9*8000 -> 157.80854 | G32: TJ/a

Sheet LCA results - cradle to gate
C1: Global warming | D1: Stratospheric ozone depletion | E1: Ionizing radiation | F1: Ozone formation, Human health | G1: Fine particulate matter formation | H1: Ozone formation, Terrestrial ecosystems | I1: Terrestrial acidification | J1: Freshwater eutrophication | K1: Marine eutrophication | L1: Terrestrial ecotoxicity | M1: Freshwater ecotoxicity | N1: Marine ecotoxicity | O1: Human carcinogenic toxicity | P1: Human non-carcinogenic toxicity | Q1: Land use | R1: Mineral resource scarcity | S1: Fossil resource scarcity | T1: Water consumption
A2: Process | C2: kg CO2 eq | D2: kg CFC11 eq | E2: kBq Co-60 eq | F2: kg NOx eq | G2: kg PM2.5 eq | H2: kg NOx eq | I2: kg SO2 eq | J2: kg P eq | K2: kg N eq | L2: kg 1,4-DCB | M2: kg 1,4-DCB | N2: kg 1,4-DCB | O2: kg 1,4-DCB | P2: kg 1,4-DCB | Q2: m2a crop eq | R2: kg Cu eq | S2: kg oil eq | T2: m3
A3: 1-propanol {GLO}| market for | Cut-off, S | B3: BAU | C3: 4.6039286 | D3: 1.464039e-06 | E3: 0.25496324 | F3: 0.016488508 | G3: 0.008409307 | H3: 0.020628871 | I3: 0.018631587 | J3: 0.0016225464 | K3: 0.00010706915 | L3: 8.8305189 | M3: 0.10247449 | N3: 0.14484011 | O3: 0.14768858 | P3: 4.519934 | Q3: 0.10146991 | R3: 0.0076205869 | S3: 2.0455138 | T3: 0.080522866
A4: Propanol; carbon dioxide from DAC; hydrogen from wind-powered water electrolysis; BAU ethylene; intermediate conversions; Abhi | B4: DAC + wind | C4: 0.77515016 | D4: 1.2052461e-07 | E4: 0.017079359 | F4: 0.0020352656 | G4: 0.0010995192 | H4: 0.0021916726 | I4: 0.0026430355 | J4: 0.00014724735 | K4: 1.5539618e-05 | L4: 1.9303644 | M4: 0.057326191 | N4: 0.072184926 | O4: 0.060129153 | P4: 0.66978841 | Q4: 0.011814994 | R4: 0.004872524 | S4: 0.93335976 | T4: 0.011605987
A5: Propanol; carbon dioxide from DAC; hydrogen from wind-powered water electrolysis; ethylene from gMeOH; intermediate conversions; Abhi | B5: DAC + wind + gE | C5: -0.99427577 | D5: 3.2029477e-07 | E5: 0.033160056 | F5: 0.0024447385 | G5: 0.0014566705 | H5: 0.0029259138 | I5: 0.0026653104 | J5: 0.00038153948 | K5: 4.315051e-05 | L5: 6.4912594 | M5: 0.19152076 | N5: 0.24003075 | O5: 0.17084891 | P5: 2.0563255 | Q5: 0.038278505 | R5: 0.016750944 | S5: 0.47854584 | T5: 0.016696454
A6: Propanol; carbon dioxide from NG power-plant; hydrogen from wind-powered water electrolysis; BAU ethylene; intermediate conversions; Abhi | B6: NG + wind | C6: 1.4688386 | D6: 1.2534162e-07 | E6: 0.017720513 | F6: 0.0024099274 | G6: 0.0011404611 | H6: 0.0025632829 | I6: 0.0027807188 | J6: 0.00014563314 | K6: 1.8796806e-05 | L6: 1.9598838 | M6: 0.055277245 | N6: 0.069555054 | O6: 0.058457365 | P6: 0.63833126 | Q6: 0.011283984 | R6: 0.004680079 | S6: 0.9148107 | T6: 0.0099969158
A7: Propanol; carbon dioxide from NG power-plant; hydrogen from wind-powered water electrolysis; ethylene from gMeOH; intermediate conversions; Abhi | B7: NG + wind + gE | C7: 1.3048446 | D7: 3.3625998e-07 | E7: 0.035285059 | F7: 0.0036864956 | G7: 0.0015923659 | H7: 0.004157557 | I7: 0.00312164 | J7: 0.00037618945 | K7: 5.3945941e-05 | L7: 6.5890966 | M7: 0.18472985 | N7: 0.23131445 | O7: 0.16530804 | P7: 1.9520658 | Q7: 0.036518556 | R7: 0.016113115 | S7: 0.4170679 | T7: 0.011363443

Sheet LCA contri - cradle to gate
A2: Wind scenario
A3: Global warming in kg CO2 eq
A4: Case | B4: Label | C4: Total | D4: Propanol | E4: Carbon dioxide | F4: Hydrogen | G4: Ethylene | H4: Electricity | I4: Cooling | J4: Emissions
A5: 1-propanol {GLO}| market for | Cut-off, S | B5: BAU | C5: 4.6039286 | D5: 4.6039286 | E5: 0 | F5: 0 | G5: 0 | H5: 0 | I5: 0 | J5: 0
A6: Propanol; carbon dioxide from DAC; hydrogen from wind-powered water electrolysis; BAU ethylene; intermediate conversions with utilities; Abhi | B6: DAC + wind | C6: 0.9703143 | D6: 0 | E6: -0.58702085 | F6: 0.10628012 | G6: 0.81993742 | H6: 0.086953464 | I6: 0.19516414 | J6: 0.349
A7: Propanol; carbon dioxide from DAC; hydrogen from wind-powered water electrolysis; ethylene from gMeOH; intermediate conversions with utilities; Abhi | B7: DAC + wind + gE | C7: -0.27930755 | D7: 0 | E7: -0.58702085 | F7: 0.10628012 | G7: -0.42968442 | H7: 0.086953464 | I7: 0.19516414 | J7: 0.349
A8: Propanol; carbon dioxide from NG power-plant; hydrogen from wind-powered water electrolysis; BAU ethylene; intermediate conversions with utilities; Abhi | B8: NG + wind | C8: 1.6640027 | D8: 0 | E8: 0.10666758 | F8: 0.10628012 | G8: 0.81993742 | H8: 0.086953464 | I8: 0.19516414 | J8: 0.349
A9: Propanol; carbon dioxide from NG power-plant; hydrogen from wind-powered water electrolysis; ethylene from gMeOH; intermediate conversions with utilities; Abhi | B9: NG + wind + gE | C9: 2.0198128 | D9: 0 | E9: 0.10666758 | F9: 0.10628012 | G9: 1.1757475 | H9: 0.086953464 | I9: 0.19516414 | J9: 0.349
A11: Human health in DALY
A12: Case | B12: Label | C12: Total | D12: Propanol | E12: Carbon dioxide | F12: Hydrogen | G12: Ethylene | H12: Electricity | I12: Cooling | J12: Emissions
A13: 1-propanol {GLO}| market for | Cut-off, S | B13: BAU | C13: 1.12561e-05 | D13: 1.12561e-05 | E13: 0 | F13: 0 | G13: 0 | H13: 0 | I13: 0 | J13: 0
A14: =$A$6 -> Propanol; carbon dioxide from DAC; hydrogen from wind-powered water electrolysis; BAU ethylene; intermediate conversions with utilities; Abhi | B14: DAC + wind | C14: 2.2241711e-06 | D14: 0 | E14: -4.6823404e-07 | F14: 5.4268468e-07 | G14: 1.157522e-06 | H14: 2.3335444e-07 | I14: 4.3497206e-07 | J14: 3.23872e-07
A15: =$A$7 -> Propanol; carbon dioxide from DAC; hydrogen from wind-powered water electrolysis; ethylene from gMeOH; intermediate conversions with utilities; Abhi | B15: DAC + wind + gE | C15: 2.869455e-06 | D15: 0 | E15: -4.6823404e-07 | F15: 5.4268468e-07 | G15: 1.8028058e-06 | H15: 2.3335444e-07 | I15: 4.3497206e-07 | J15: 3.23872e-07
A16: =$A$8 -> Propanol; carbon dioxide from NG power-plant; hydrogen from wind-powered water electrolysis; BAU ethylene; intermediate conversions with utilities; Abhi | B16: NG + wind | C16: 2.8777372e-06 | D16: 0 | E16: 1.8533206e-07 | F16: 5.4268468e-07 | G16: 1.157522e-06 | H16: 2.3335444e-07 | I16: 4.3497206e-07 | J16: 3.23872e-07
A17: =$A$9 -> Propanol; carbon dioxide from NG power-plant; hydrogen from wind-powered water electrolysis; ethylene from gMeOH; intermediate conversions with utilities; Abhi | B17: NG + wind + gE | C17: 5.0355962e-06 | D17: 0 | E17: 1.8533206e-07 | F17: 5.4268468e-07 | G17: 3.315381e-06 | H17: 2.3335444e-07 | I17: 4.3497206e-07 | J17: 3.23872e-07
A19: Ecosystems in species.yr
A20: Case | B20: Label | C20: Total | D20: Propanol | E20: Carbon dioxide | F20: Hydrogen | G20: Ethylene | H20: Electricity | I20: Cooling | J20: Emissions
A21: 1-propanol {GLO}| market for | Cut-off, S | B21: BAU | C21: 2.26645e-08 | D21: 2.26645e-08 | E21: 0 | F21: 0 | G21: 0 | H21: 0 | I21: 0 | J21: 0
A22: =$A$6 -> Propanol; carbon dioxide from DAC; hydrogen from wind-powered water electrolysis; BAU ethylene; intermediate conversions with utilities; Abhi | B22: DAC + wind | C22: 4.5053409e-09 | D22: 0 | E22: -1.5394803e-09 | F22: 6.7645868e-10 | G22: 2.943711e-09 | H22: 3.8019169e-10 | I22: 1.0672331e-09 | J22: 9.772267e-10
A23: =$A$7 -> Propanol; carbon dioxide from DAC; hydrogen from wind-powered water electrolysis; ethylene from gMeOH; intermediate conversions with utilities; Abhi | B23: DAC + wind + gE | C23: 2.5190637e-09 | D23: 0 | E23: -1.5394803e-09 | F23: 6.7645868e-10 | G23: 9.5743379e-10 | H23: 3.8019169e-10 | I23: 1.0672331e-09 | J23: 9.772267e-10
A24: =$A$8 -> Propanol; carbon dioxide from NG power-plant; hydrogen from wind-powered water electrolysis; BAU ethylene; intermediate conversions with utilities; Abhi | B24: NG + wind | C24: 6.495851e-09 | D24: 0 | E24: 4.5102979e-10 | F24: 6.7645868e-10 | G24: 2.943711e-09 | H24: 3.8019169e-10 | I24: 1.0672331e-09 | J24: 9.772267e-10
A25: =$A$9 -> Propanol; carbon dioxide from NG power-plant; hydrogen from wind-powered water electrolysis; ethylene from gMeOH; intermediate conversions with utilities; Abhi | B25: NG + wind + gE | C25: 9.1162939e-09 | D25: 0 | E25: 4.5102979e-10 | F25: 6.7645868e-10 | G25: 5.5641539e-09 | H25: 3.8019169e-10 | I25: 1.0672331e-09 | J25: 9.772267e-10
A27: Resources in USD2013
A28: Case | B28: Label | C28: Total | D28: Propanol | E28: Carbon dioxide | F28: Hydrogen | G28: Ethylene | H28: Electricity | I28: Cooling | J28: Emissions
A29: 1-propanol {GLO}| market for | Cut-off, S | B29: BAU | C29: 0.68911549 | D29: 0.68911549 | E29: 0 | F29: 0 | G29: 0 | H29: 0 | I29: 0 | J29: 0
A30: =$A$6 -> Propanol; carbon dioxide from DAC; hydrogen from wind-powered water electrolysis; BAU ethylene; intermediate conversions with utilities; Abhi | B30: DAC + wind | C30: 0.3916478 | D30: 0 | E30: 0.039548457 | F30: 0.0080714424 | G30: 0.32368224 | H30: 0.0039008767 | I30: 0.016444787 | J30: 0
A31: =$A$7 -> Propanol; carbon dioxide from DAC; hydrogen from wind-powered water electrolysis; ethylene from gMeOH; intermediate conversions with utilities; Abhi | B31: DAC + wind + gE | C31: 0.19849847 | D31: 0 | E31: 0.039548457 | F31: 0.0080714424 | G31: 0.13053291 | H31: 0.0039008767 | I31: 0.016444787 | J31: 0
A32: =$A$8 -> Propanol; carbon dioxide from NG power-plant; hydrogen from wind-powered water electrolysis; BAU ethylene; intermediate conversions with utilities; Abhi | B32: NG + wind | C32: 0.38486787 | D32: 0 | E32: 0.032768529 | F32: 0.0080714424 | G32: 0.32368224 | H32: 0.0039008767 | I32: 0.016444787 | J32: 0
A33: =$A$9 -> Propanol; carbon dioxide from NG power-plant; hydrogen from wind-powered water electrolysis; ethylene from gMeOH; intermediate conversions with utilities; Abhi | B33: NG + wind + gE | C33: 0.17602747 | D33: 0 | E33: 0.032768529 | F33: 0.0080714424 | G33: 0.11484184 | H33: 0.0039008767 | I33: 0.016444787 | J33: 0
A37: Grid scenario
A38: Global warming in kg CO2 eq
A39: Case | B39: Label | C39: Total | D39: Propanol | E39: Carbon dioxide | F39: Hydrogen | G39: Ethylene | H39: Electricity | I39: Cooling | J39: Emissions
A40: 1-propanol {GLO}| market for | Cut-off, S | B40: BAU | C40: 4.6039286 | D40: 4.6039286 | E40: 0 | F40: 0 | G40: 0 | H40: 0 | I40: 0 | J40: 0
A41: Propanol; carbon dioxide from DAC; hydrogen from grid-powered water electrolysis; BAU ethylene; intermediate conversions with utilities; Abhi | B41: DAC + grid | C41: 6.0384535 | D41: 0 | E41: -0.41468634 | F41: 5.0020848 | G41: 0.81993742 | H41: 0.086953464 | I41: 0.19516414 | J41: 0.349
A42: Propanol; carbon dioxide from DAC; hydrogen from grid-powered water electrolysis; ethylene from gMeOH; intermediate conversions with utilities; Abhi | B42: DAC + grid + gE | C42: 16.932148 | D42: 0 | E42: -0.41468634 | F42: 5.0020848 | G42: 11.713632 | H42: 0.086953464 | I42: 0.19516414 | J42: 0.349
A43: Propanol; carbon dioxide from NG power-plant; hydrogen from grid-powered water electrolysis; BAU ethylene; intermediate conversions with utilities; Abhi | B43: NG + grid | C43: 6.5598074 | D43: 0 | E43: 0.10666758 | F43: 5.0020848 | G43: 0.81993742 | H43: 0.086953464 | I43: 0.19516414 | J43: 0.349
A44: Propanol; carbon dioxide from NG power-plant; hydrogen from grid-powered water electrolysis; ethylene from gMeOH; intermediate conversions with utilities; Abhi | B44: NG + grid + gE | C44: 18.660093 | D44: 0 | E44: 0.10666758 | F44: 5.0020848 | G44: 12.920223 | H44: 0.086953464 | I44: 0.19516414 | J44: 0.349
A46: Human health in DALY
A47: Case | B47: Label | C47: Total | D47: Propanol | E47: Carbon dioxide | F47: Hydrogen | G47: Ethylene | H47: Electricity | I47: Cooling | J47: Emissions
A48: 1-propanol {GLO}| market for | Cut-off, S | B48: BAU | C48: 1.12561e-05 | D48: 1.12561e-05 | E48: 0 | F48: 0 | G48: 0 | H48: 0 | I48: 0 | J48: 0
...

Sheet Economic results
A1: Cost of production assuming reaction efficiencies with recycle and only raw material costs
B3: Price [$/unit] | C3: Input [unit/t propanol] | D3: Amount [$/t propanol]
A4: Carbon dioxide from NG | B4: 80.3 | C4: ='Aspen data'!E4 -> 0.84717282 | D4: =B4*C4 -> 68.027977
A5: Carbon dioxide from DAC | B5: =(94+232)/2 -> 163 | C5: =C4 -> 0.84717282 | D5: =B5*C5 -> 138.08917
A6: Hydrogen from wind | B6: 3286.4 | C6: ='Aspen data'!E5 -> 0.10709997 | D6: =B6*C6 -> 351.97335
A7: Ethylene BAU | B7: 1293 | C7: ='Aspen data'!E6 -> 0.54151671 | D7: =B7*C7 -> 700.18111
A8: Ethylene - gMeOH - NG | B8: 2300 | C8: =C7 -> 0.54151671 | D8: =B8*C8 -> 1245.4884
A9: Ethylene - gMeOH - DAC | B9: 2600 | C9: =C7 -> 0.54151671 | D9: =B9*C9 -> 1407.9435
A10: Electricity | B10: 0.0696 | C10: ='Aspen data'!B14*1000 -> 117.99716 | D10: =B10*C10 -> 8.2126024 | E10: kWh/t
A11: Cooling | B11: =3.6*10^-2 -> 0.036 | C11: ='Aspen data'!F21*1000 -> 5503.7139 | D11: =B11*F12 -> 9.466493 | E11: MJ/t | F11: =C11*10^6/4186/5 -> 262958.14 | G11: kg
F12: =F11/1000 -> 262.95814 | G12: m3
A14: Market price | B14: 1690 | C14: $/t propanol
A15: NG + wind | B15: =D4+D6+D7+D10+D11 -> 1137.8615 | C15: $/t propanol | D15: =($B$14-B15)/$B$14 -> 0.32670915
A16: NG + wind + gE | B16: =D4+D6+D8+D10+D11 -> 1683.1689 | C16: $/t propanol | D16: =($B$14-B16)/$B$14 -> 0.0040420913
A17: DAC + wind | B17: =D5+D6+D7+D10+D11 -> 1207.9227 | C17: $/t propanol | D17: =($B$14-B17)/$B$14 -> 0.28525282
A18: DAC + wind + gE | B18: =D5+D6+D9+D10+D11 -> 1915.6851 | C18: $/t propanol | D18: =($B$14-B18)/$B$14 -> -0.13354146
