Workbook

Sheet CAPEX
A1: Cost factors
A2: Equipment erection | B2: fer | C2: 0.3
A3: Piping | B3: fp | C3: 0.8
A4: Instrumentation and control | B4: fi | C4: 0.3
A5: Electrical | B5: fel | C5: 0.2
A6: Civil | B6: fc | C6: 0.3
A7: Structures and buildings | B7: fs | C7: 0.2
A8: Lagging and paint | B8: fl | C8: 0.1
A9: Material factor for 304 SS | B9: fm | C9: 1.3
A12: Equipment | B12: Equipment approximated as | C12: Dimension needed | D12: Value | E12: a | F12: b | G12: n | H12: Purchased Cost (Ce,i,a) | L12: Equipment | M12: Internal diameter (m) | N12: h (m) | O12: External diameter (m) | P12: Area for shell (m2) | Q12: Volume | R12: Density (kg/m3) | S12: Shell mass (kg) | T12: N stages
A13: Compressors | L13: Reactor | M13: 0.9144 | N13: =3.9624+2*0.25*M13 -> 4.4196 | O13: =M13+0.0254 -> 0.9398 | P13: =PI()*(O13*O13-M13*M13)/4 -> 0.036989646 | Q13: =P13*N13 -> 0.16347944 | R13: 8000 | S13: =R13*Q13 -> 1307.8355
A14: Centrifugal Compressor | B14: Centrifugal Compressor | C14: Power, kW | D14: 211.75957 | E14: 580000 | F14: 20000 | G14: 0.6 | H14: =(E14+(F14*(D14^G14)))/1000000 -> 1.0772054 | L14: Reactor | M14: 0.9144 | N14: =3.9624+2*0.25*M14 -> 4.4196 | O14: =M14+0.0254 -> 0.9398 | P14: =PI()*(O14*O14-M14*M14)/4 -> 0.036989646 | Q14: =P14*N14 -> 0.16347944 | R14: 8000 | S14: =R14*Q14 -> 1307.8355
A15: Centrifugal Compressor | B15: Centrifugal Compressor | C15: Power, kW | D15: 219.90135 | E15: 580000 | F15: 20000 | G15: 0.6 | H15: =(E15+(F15*(D15^G15)))/1000000 -> 1.0885887 | L15: Reactor | M15: 3.9624 | N15: =19.812+2*0.25*M15 -> 21.7932 | O15: =M15+0.0254 -> 3.9878 | P15: =PI()*(O15*O15-M15*M15)/4 -> 0.15859944 | Q15: =P15*N15 -> 3.4563893 | R15: 8000 | S15: =R15*Q15 -> 27651.115
A16: Centrifugal Compressor | B16: Centrifugal Compressor | C16: Power, kW | D16: 762.36185 | E16: 580000 | F16: 20000 | G16: 0.6 | H16: =(E16+(F16*(D16^G16)))/1000000 -> 1.6523256 | L16: B10 | M16: 1.0668 | N16: =3.6576+2*0.25*M16 -> 4.191 | O16: =M16+0.0254 -> 1.0922 | P16: =PI()*(O16*O16-M16*M16)/4 -> 0.043070136 | Q16: =P16*N16 -> 0.18050694 | R16: 8000 | S16: =R16*Q16 -> 1444.0555
A17: Centrifugal Compressor | B17: Centrifugal Compressor | C17: Power, kW | D17: 204.81885 | E17: 580000 | F17: 20000 | G17: 0.6 | H17: =(E17+(F17*(D17^G17)))/1000000 -> 1.0673623 | L17: B14 | M17: 0.9144 | N17: =3.6576+2*0.25*M17 -> 4.1148 | O17: =M17+0.0254 -> 0.9398 | P17: =PI()*(O17*O17-M17*M17)/4 -> 0.036989646 | Q17: =P17*N17 -> 0.152205 | R17: 8000 | S17: =R17*Q17 -> 1217.64
A18: Centrifugal Compressor | B18: Centrifugal Compressor | C18: Power, kW | D18: 201.71516 | E18: 580000 | F18: 20000 | G18: 0.6 | H18: =(E18+(F18*(D18^G18)))/1000000 -> 1.0629177 | L18: B16 | M18: 1.2192 | N18: =3.6576+2*0.25*M18 -> 4.2672 | O18: =M18+0.0254 -> 1.2446 | P18: =PI()*(O18*O18-M18*M18)/4 -> 0.049150625 | Q18: =P18*N18 -> 0.20973555 | R18: 8000 | S18: =R18*Q18 -> 1677.8844
A19: Centrifugal Compressor | B19: Centrifugal Compressor | C19: Power, kW | D19: 199.44307 | E19: 580000 | F19: 20000 | G19: 0.6 | H19: =(E19+(F19*(D19^G19)))/1000000 -> 1.0596466 | L19: B24 | M19: 0.9144 | N19: =3.6576+2*0.25*M19 -> 4.1148 | O19: =M19+0.0254 -> 0.9398 | P19: =PI()*(O19*O19-M19*M19)/4 -> 0.036989646 | Q19: =P19*N19 -> 0.152205 | R19: 8000 | S19: =R19*Q19 -> 1217.64
A20: Pumps | L20: B37 | M20: 1.2192 | N20: =3.6576+2*0.25*M20 -> 4.2672 | O20: =M20+0.0254 -> 1.2446 | P20: =PI()*(O20*O20-M20*M20)/4 -> 0.049150625 | Q20: =P20*N20 -> 0.20973555 | R20: 8000 | S20: =R20*Q20 -> 1677.8844
A21: Centrifugal Pump | B21: Pump | C21: Flow, litres/s | D21: 25.454314 | E21: 8000 | F21: 240 | G21: 0.9 | H21: =(E21+(F21*(D21^G21)))/1000000 -> 0.012419738 | L21: B8 | M21: 1.8288 | N21: =0.6096*T21 -> 6.096 | O21: =M21+0.0254 -> 1.8542 | P21: =PI()*(O21*O21-M21*M21)/4 -> 0.073472584 | Q21: =P21*N21 -> 0.44788887 | R21: 8000 | S21: =R21*Q21 -> 3583.111 | T21: 10
A22: Turbines | L22: B18 | M22: 0.9144 | N22: =0.6096*T22 -> 6.096 | O22: =M22+0.0254 -> 0.9398 | P22: =PI()*(O22*O22-M22*M22)/4 -> 0.036989646 | Q22: =P22*N22 -> 0.22548888 | R22: 8000 | S22: =R22*Q22 -> 1803.9111 | T22: 10
A23: Turbine | B23: Turbine | C23: Power, kW | D23: 297.60548 | E23: -14000 | F23: 1900 | G23: 0.75 | H23: =(E23+(F23*(D23^G23)))/1000000 -> 0.12213954
A24: Turbine | B24: Turbine | C24: Power, kW | D24: 258.69505 | E24: -14000 | F24: 1900 | G24: 0.75 | H24: =(E24+(F24*(D24^G24)))/1000000 -> 0.10855885
A25: Heat exchangers | I25: Total area | J25: Shells | M25: Compressors | N25: =SUM(H14:H19) -> 7.0080464
A26: E-136 | B26: U Tube HEX | C26: Area | D26: =I26/J26 -> 282.7743 | E26: 28000 | F26: 54 | G26: 1.2 | H26: =(E26+(F26*(D26^G26)))/1000000*J26 -> 0.15043906 | I26: 565.5486 | J26: 2 | M26: Pumps | N26: =SUM(H21) -> 0.012419738
A27: E-138 | B27: U Tube HEX | C27: Area | D27: =I27/J27 -> 54.369784 | E27: 28000 | F27: 54 | G27: 1.2 | H27: =(E27+(F27*(D27^G27)))/1000000*J27 -> 0.034528643 | I27: 54.369784 | J27: 1 | M27: Turbines | N27: =SUM(H23:H24) -> 0.2306984
A28: E-130 | B28: U Tube HEX | C28: Area | D28: =I28/J28 -> 17.191757 | E28: 28000 | F28: 54 | G28: 1.2 | H28: =(E28+(F28*(D28^G28)))/1000000*J28 -> 0.059279503 | I28: 34.383513 | J28: 2 | M28: Heat exchangers | N28: =SUM(H26:H52) -> 1.9468801
A29: E-132 | B29: U Tube HEX | C29: Area | D29: =I29/J29 -> 0.88519532 | E29: 28000 | F29: 54 | G29: 1.2 | H29: =(E29+(F29*(D29^G29)))/1000000*J29 -> 0.028046649 | I29: 0.88519532 | J29: 1 | M29: Reactors | N29: =SUM(H54:H56) -> 0.59369223
A30: E-122 | B30: U Tube HEX | C30: Area | D30: =I30/J30 -> 106.455 | E30: 28000 | F30: 54 | G30: 1.2 | H30: =(E30+(F30*(D30^G30)))/1000000*J30 -> 0.085243073 | I30: 212.90999 | J30: 2 | M30: Separation | N30: =SUM(H58:H68) -> 0.5895808
A31: E-120 | B31: U Tube HEX | C31: Area | D31: =I31/J31 -> 154.99445 | E31: 28000 | F31: 54 | G31: 1.2 | H31: =(E31+(F31*(D31^G31)))/1000000*J31 -> 0.15284849 | I31: 464.98335 | J31: 3 | N31: =SUM(N25:N30) -> 10.381318
A32: E-124 | B32: U Tube HEX | C32: Area | D32: =I32/J32 -> 1.7461325 | E32: 28000 | F32: 54 | G32: 1.2 | H32: =(E32+(F32*(D32^G32)))/1000000*J32 -> 0.028105411 | I32: 1.7461325 | J32: 1
A33: E-117 | B33: U Tube HEX | C33: Area | D33: =I33/J33 -> 100.09703 | E33: 28000 | F33: 54 | G33: 1.2 | H33: =(E33+(F33*(D33^G33)))/1000000*J33 -> 0.041579982 | I33: 100.09703 | J33: 1
A34: E-113 | B34: U Tube HEX | C34: Area | D34: =I34/J34 -> 80.091115 | E34: 28000 | F34: 54 | G34: 1.2 | H34: =(E34+(F34*(D34^G34)))/1000000*J34 -> 0.0383919 | I34: 80.091115 | J34: 1
A35: E-115 | B35: U Tube HEX | C35: Area | D35: =I35/J35 -> 201.51017 | E35: 28000 | F35: 54 | G35: 1.2 | H35: =(E35+(F35*(D35^G35)))/1000000*J35 -> 0.059444893 | I35: 201.51017 | J35: 1
A36: E-133 | B36: U Tube HEX | C36: Area | D36: =I36/J36 -> 131.62624 | E36: 28000 | F36: 54 | G36: 1.2 | H36: =(E36+(F36*(D36^G36)))/1000000*J36 -> 0.046862737 | I36: 131.62624 | J36: 1
A37: E-135 | B37: U Tube HEX | C37: Area | D37: =I37/J37 -> 100.60444 | E37: 28000 | F37: 54 | G37: 1.2 | H37: =(E37+(F37*(D37^G37)))/1000000*J37 -> 0.04166263 | I37: 100.60444 | J37: 1
A38: E-137 | B38: U Tube HEX | C38: Area | D38: =I38/J38 -> 53.678385 | E38: 28000 | F38: 54 | G38: 1.2 | H38: =(E38+(F38*(D38^G38)))/1000000*J38 -> 0.068858286 | I38: 107.35677 | J38: 2
A39: E-139 | B39: U Tube HEX | C39: Area | D39: =I39/J39 -> 27.765613 | E39: 28000 | F39: 54 | G39: 1.2 | H39: =(E39+(F39*(D39^G39)))/1000000*J39 -> 0.030914758 | I39: 27.765613 | J39: 1
A40: E-131 | B40: U Tube HEX | C40: Area | D40: =I40/J40 -> 106.76511 | E40: 28000 | F40: 54 | G40: 1.2 | H40: =(E40+(F40*(D40^G40)))/1000000*J40 -> 0.042672664 | I40: 106.76511 | J40: 1
A41: E-129 | B41: U Tube HEX | C41: Area | D41: =I41/J41 -> 45.191537 | E41: 28000 | F41: 54 | G41: 1.2 | H41: =(E41+(F41*(D41^G41)))/1000000*J41 -> 0.066459051 | I41: 90.383074 | J41: 2
A42: E-116 | B42: U Tube HEX | C42: Area | D42: =I42/J42 -> 196.13956 | E42: 28000 | F42: 54 | G42: 1.2 | H42: =(E42+(F42*(D42^G42)))/1000000*J42 -> 0.11688383 | I42: 392.27912 | J42: 2
...

Sheet OPEX
K1: Grid electricity IEA
K2: Germany | L2: France | M2: Japan | N2: India | O2: Australia | P2: United States
B3: Material | C3: Unit | D3: Quantity | E3: Price 2023 ($/unit) | F3: 2023 costs | K3: 153.58 | L3: 139.87 | M3: 111.24 | N3: 74.56 | O3: 60.72 | P3: 40.07
B4: Raw material costs | K4: 124.39 | L4: 98.7 | M4: 62.03 | N4: 55.37 | O4: 78.7 | P4: 36.95
B5: Carbon dioxide | C5: ton/hr | D5: 9.3315581 | E5: 362 | F5: =D5*E5 -> 3378.024 | K5: 90.02 | L5: 87.85 | M5: 93.5 | O5: 57.12 | P5: 53.16
B6: Hydrogen | C6: ton/hr | D6: 1.2656947 | E6: 6072.2537 | F6: =D6*E6 -> 7685.6192 | K6: 124.66 | L6: 158.74 | M6: 95.76 | O6: 57.36 | P6: 37.95
B7: Ethylene | C7: ton/hr | D7: 5.868313 | E7: 908.33333 | F7: =D7*E7 -> 5330.3843 | P7: =AVERAGE(K3:P6) -> 86.013636
B8: MTO Ethylene | C8: ton/hr | D8: =D7 -> 5.868313 | E8: 4235.8904 | F8: =D8*E8 -> 24857.53
B9: Monoethanolamine | C9: ton/hr | D9: 0.77444962 | E9: 0 | F9: =D9*E9 -> 0 | H9: 2022
B10: Process water | C10: ton/hr | D10: 12.614908 | E10: 0 | F10: =D10*E10 -> 0 | I10: Low | J10: High | K10: Average
B11: Utility costs | H11: Carbon dioxide | I11: 269 | J11: 623 | K11: 362
B12: Cooling water | C12: GJ/hr | D12: 133.45531 | E12: =0.3808*C22/C20 -> 0.50014867 | F12: =D12*E12 -> 66.747496 | H12: Hydrogen | I12: 5190 | J12: 7290 | K12: 6210
B13: Grid electricity | C13: kWh | D13: 1324.5542 | E13: =P7/1000 -> 0.086013636 | F13: =D13*E13 -> 113.92972 | H13: Ethylene | I13: 585 | J13: 1164.1667 | K13: 908.33333
B14: Natural gas heating | C14: GJ/hr | D14: 107.60792 | E14: =447.388911263905/47.1 -> 9.498703 | F14: =D14*E14 -> 1022.1356 | H14: MTO ethylene | I14: 4286.7636 | J14: 4378.3292 | K14: 4331.9796
B15: OPEX (fossil ethylene) | C15: M$/year | F15: =(F5+F6+F7+F9+F10+F12+F13+F14)/1000000*8000 -> 140.77472
B16: OPEX (MTO ethylene) | C16: M$/year | F16: =(F5+F6+F8+F9+F10+F12+F13+F14)/1000000*8000 -> 296.99189 | H16: 2023
H17: Carbon dioxide | I17: =I11*1 -> 269 | J17: =J11*1 -> 623 | K17: =K11*1 -> 362
B18: Reference Data | H18: Hydrogen | I18: =I12*$C$22/$C$21 -> 5074.8787 | J18: =J12*$C$22/$C$21 -> 7128.2978 | K18: =K12*$C$22/$C$21 -> 6072.2537
B19: CEPCI 2018 | C19: 603.1 | H19: Ethylene | I19: =I13*1 -> 585 | J19: =J13*1 -> 1164.1667 | K19: =K13*1 -> 908.33333
B20: CEPCI 2019 | C20: 607.5 | H20: MTO ethylene | I20: =I14*$C$22/$C$21 -> 4191.6773 | J20: =J14*$C$22/$C$21 -> 4281.2119 | K20: =K14*$C$22/$C$21 -> 4235.8904
B21: CEPCI 2022 | C21: 816
B22: CEPCI 2023 | C22: 797.9

Sheet summary
B2: Production capacity: 130 kt/year | E2: Production capacity: 130 kt/year
B3: Purchased equipment cost 2023 (M$/year) | C3: =CAPEX!B74 -> 15.543729 | E3: Purchased equipment cost 2023 (M$/year) | F3: =CAPEX!E74 -> 0
B4: Installed capital cost | C4: =CAPEX!B77 -> 58.133547 | E4: Installed capital cost | F4: =CAPEX!E77 -> 0
B5: Offsites (OS) | C5: =CAPEX!B78 -> 17.440064 | E5: Offsites (OS) | F5: =CAPEX!E78 -> 0
B6: Design and engineering (D&E) | C6: =CAPEX!B79 -> 22.672083 | E6: Design and engineering (D&E) | F6: =CAPEX!E79 -> 0
B7: Contingency (X) | C7: =CAPEX!B80 -> 7.5573612 | E7: Contingency (X) | F7: =CAPEX!E80 -> 0
B8: Fixed capital investment | C8: =CAPEX!B81 -> 105.80306 | E8: Fixed capital investment | F8: =CAPEX!E81 -> 0
B9: Working capital | C9: =CAPEX!B82 -> 15.870458 | E9: Working capital | F9: =CAPEX!E82 -> 0
B10: Total investment | C10: =CAPEX!B83 -> 121.67351 | E10: Total investment | F10: =CAPEX!E83 -> 0
B11: Labor costs | C11: 0 | E11: Labor costs | F11: 0
B12: Maintanance costs | C12: 0 | E12: Maintanance costs | F12: 0
B13: Overhead expenses | C13: 0 | E13: Overhead expenses | F13: 0
B14: Interest | C14: 0 | E14: Interest | F14: 0
B15: Project lifetime | C15: =CAPEX!B84 -> 25 | E15: Project lifetime | F15: =CAPEX!E84 -> 0
B16: Interest rate | C16: =CAPEX!B85 -> 0.12 | E16: Interest rate | F16: =CAPEX!E85 -> 0
B17: ACCR | C17: =CAPEX!B86 -> 0.12749997 | E17: ACCR | F17: =CAPEX!E86 -> 0
B18: Allocation factor | C18: 0.53676923 | E18: Allocation factor | F18: =C18 -> 0.53676923
B19: CAPEX (M$/year) | C19: =CAPEX!B88*C18 -> 8.3270994 | E19: CAPEX (M$/year) | F19: =C19 -> 8.3270994
B20: Fixed production costs (M$/year) | C20: 0 | E20: Fixed production costs (M$/year) | F20: =C20 -> 0
B21: OPEX (M$/year) | C21: =OPEX!F15 -> 140.77472 | E21: OPEX (M$/year) | F21: =OPEX!F16 -> 296.99189
B22: Total expenses (M$/year) | C22: =(C19+C20+C21) -> 149.10182 | E22: Total expenses (M$/year) | F22: =(F19+F20+F21) -> 305.31899
B23: Total expenses ($/hr) | C23: =(C22)*1000000/8000 -> 18637.728 | E23: Total expenses ($/hr) | F23: =(F22)*1000000/8000 -> 38164.874
B24: Total product Produced (kg/hr) | C24: 12493.912 | E24: Total product Produced (kg/hr) | F24: 12493.912
B25: Cost per kg (fossil) | C25: =C23/C24 -> 1.4917448 | E25: Cost per kg (biomethane) | F25: =F23/F24 -> 3.0546777

Sheet methanol-to-olefins
A1: Flow | B1: kg per kg ethylene
A2: Methanol | B2: 2.519 | C2: =B2*D2 -> 4.1047861 | D2: 1.62953 | E2: Nabera et al.
A3: Electricity | B3: 0.143 | C3: =B3*D3 -> 0.01229995 | D3: 0.086013636 | E3: IEA
A4: Steam | B4: 0.022 | C4: =B4*D4 -> 0.0003432 | D4: =15.6/1000 -> 0.0156 | E4: Ioannou et al.
A5: Cooling water | B5: =0.0002 -> 0.0002 | C5: =B5*D5 -> 2.0915e-09 | D5: =0.5/10^6*4.183*5 -> 1.04575e-05 | E5: This work
A6: CAPEX | B6: 0.2609 | C6: =B6 -> 0.2609 | D6: - | E6: Ioannou et al.
C7: =SUM(C2:C6) -> 4.3783292
A10: CEPCI 2019 | B10: 607.5
A11: CEPCI 2022 | B11: 816
A12: CEPCI 2023 | B12: 797.9
