Workbook

Sheet CAPEX
A1: Cost factors
A2: Equipment erection | B2: fer | C2: 0.3
A3: Piping | B3: fp | C3: 0.8
A4: Instrumentation and control | B4: fi | C4: 0.3
A5: Electrical | B5: fel | C5: 0.2
A6: Civil | B6: fc | C6: 0.3
A7: Structures and buildings | B7: fs | C7: 0.2
A8: Lagging and paint | B8: fl | C8: 0.1
A9: Material factor for 304 SS | B9: fm | C9: 1.3
A12: Equipment | B12: Equipment approximated as | C12: Dimension needed | D12: Value | E12: a | F12: b | G12: n | H12: Purchased Cost (Ce,i,a) | J12: Equipment | K12: Internal diameter (m) | L12: h (m) | M12: External diameter (m) | N12: Area for shell (m2) | O12: Volume | P12: Density (kg/m3) | Q12: Shell mass (kg)
A13: Compressors | J13: V-100 | K13: 6.096 | L13: 21.336 | M13: =K13+0.0254 -> 6.1214 | N13: =PI()*(M13*M13-K13*K13)/4 -> 0.2437263 | O13: =N13*L13 -> 5.2001443 | P13: 8000 | Q13: =P13*O13 -> 41601.154
A14: K-100 | B14: Centrifugal compressor | C14: Power, kW | D14: 3968.315 | E14: 580000 | F14: 20000 | G14: 0.6 | H14: =(E14+(F14*(D14^G14)))/1000000 -> 3.465318 | J14: V-101 | K14: 5.334 | L14: 18.669 | M14: =K14+0.0254 -> 5.3594 | N14: =PI()*(M14*M14-K14*K14)/4 -> 0.21332385 | O14: =N14*L14 -> 3.9825429 | P14: 8000 | Q14: =P14*O14 -> 31860.343
A15: K-101 | B15: Centrifugal compressor | C15: Power, kW | D15: 3897.1179 | E15: 580000 | F15: 20000 | G15: 0.6 | H15: =(E15+(F15*(D15^G15)))/1000000 -> 3.4341456 | J15: V-102 | K15: 5.334 | L15: 18.669 | M15: =K15+0.0254 -> 5.3594 | N15: =PI()*(M15*M15-K15*K15)/4 -> 0.21332385 | O15: =N15*L15 -> 3.9825429 | P15: 8000 | Q15: =P15*O15 -> 31860.343
A16: K-102 | B16: Centrifugal compressor | C16: Power, kW | D16: 3874.3885 | E16: 580000 | F16: 20000 | G16: 0.6 | H16: =(E16+(F16*(D16^G16)))/1000000 -> 3.4241461 | J16: V-103 | K16: 6.5532 | L16: 22.9362 | M16: =K16+0.0254 -> 6.5786 | N16: =PI()*(M16*M16-K16*K16)/4 -> 0.26196777 | O16: =N16*L16 -> 6.0085451 | P16: 8000 | Q16: =P16*O16 -> 48068.361
A17: K-103 | B17: Centrifugal compressor | C17: Power, kW | D17: 2652.1762 | E17: 580000 | F17: 20000 | G17: 0.6 | H17: =(E17+(F17*(D17^G17)))/1000000 -> 2.8456427 | J17: V-104 | K17: 0.6096 | L17: 3.3528 | M17: =K17+0.0254 -> 0.635 | N17: =PI()*(M17*M17-K17*K17)/4 -> 0.024828666 | O17: =N17*L17 -> 0.083245553 | P17: 8000 | Q17: =P17*O17 -> 665.96442
A18: K-104 | B18: Centrifugal compressor | C18: Power, kW | D18: 1.8756644 | E18: 580000 | F18: 20000 | G18: 0.6 | H18: =(E18+(F18*(D18^G18)))/1000000 -> 0.6091691 | J18: V-105 | K18: 3.3528 | L18: 11.7348 | M18: =K18+0.0254 -> 3.3782 | N18: =PI()*(M18*M18-K18*K18)/4 -> 0.13427748 | O18: =N18*L18 -> 1.5757194 | P18: 8000 | Q18: =P18*O18 -> 12605.755
A19: K-105 | B19: Centrifugal compressor | C19: Power, kW | D19: 2.0314086 | E19: 580000 | F19: 20000 | G19: 0.6 | H19: =(E19+(F19*(D19^G19)))/1000000 -> 0.61059908 | J19: V-106 | K19: 1.0668 | L19: 5.8674 | M19: =K19+0.0254 -> 1.0922 | N19: =PI()*(M19*M19-K19*K19)/4 -> 0.043070136 | O19: =N19*L19 -> 0.25270971 | P19: 8000 | Q19: =P19*O19 -> 2021.6777
A20: K-106 | B20: Centrifugal compressor | C20: Power, kW | D20: 2.0942139 | E20: 580000 | F20: 20000 | G20: 0.6 | H20: =(E20+(F20*(D20^G20)))/1000000 -> 0.61116324 | J20: V-107 | K20: 0.3048 | L20: 1.6764 | M20: =K20+0.0254 -> 0.3302 | N20: =PI()*(M20*M20-K20*K20)/4 -> 0.012667687 | O20: =N20*L20 -> 0.02123611 | P20: 8000 | Q20: =P20*O20 -> 169.88888
A21: K-107 | B21: Centrifugal compressor | C21: Power, kW | D21: 1.4371651 | E21: 580000 | F21: 20000 | G21: 0.6 | H21: =(E21+(F21*(D21^G21)))/1000000 -> 0.60486188 | J21: V-108 | K21: 1.3716 | L21: 7.5438 | M21: =K21+0.0254 -> 1.397 | N21: =PI()*(M21*M21-K21*K21)/4 -> 0.055231115 | O21: =N21*L21 -> 0.41665249 | P21: 8001 | Q21: =P21*O21 -> 3333.6365
A22: K-108 | B22: Centrifugal compressor | C22: Power, kW | D22: 902.01095 | E22: 580000 | F22: 20000 | G22: 0.6 | H22: =(E22+(F22*(D22^G22)))/1000000 -> 1.7661977 | J22: V-109 | K22: 1.3716 | L22: 7.5438 | M22: =K22+0.0254 -> 1.397 | N22: =PI()*(M22*M22-K22*K22)/4 -> 0.055231115 | O22: =N22*L22 -> 0.41665249 | P22: 8002 | Q22: =P22*O22 -> 3334.0532
A23: K-109 | B23: Centrifugal compressor | C23: Power, kW | D23: 966.97096 | E23: 580000 | F23: 20000 | G23: 0.6 | H23: =(E23+(F23*(D23^G23)))/1000000 -> 1.816739 | J23: T-100 | K23: 1.5415 | L23: =0.6096*10 -> 6.096 | M23: =K23+0.0254 -> 1.5669 | N23: =PI()*(M23*M23-K23*K23)/4 -> 0.062009824 | O23: =N23*L23 -> 0.37801189 | P23: 8000 | Q23: =P23*O23 -> 3024.0951
A24: K-110 | B24: Centrifugal compressor | C24: Power, kW | D24: 945.80368 | E24: 580000 | F24: 20000 | G24: 0.6 | H24: =(E24+(F24*(D24^G24)))/1000000 -> 1.8004236 | J24: T-101 | K24: 2.1346667 | L24: =0.6096*3 -> 1.8288 | M24: =K24+0.0254 -> 2.1600667 | N24: =PI()*(M24*M24-K24*K24)/4 -> 0.085676122 | O24: =N24*L24 -> 0.15668449 | P24: 8000 | Q24: =P24*O24 -> 1253.4759
A25: K-111 | B25: Centrifugal compressor | C25: Power, kW | D25: 554.29395 | E25: 580000 | F25: 20000 | G25: 0.6 | H25: =(E25+(F25*(D25^G25)))/1000000 -> 1.4656744 | J25: T-102 | K25: 1.224 | L25: 0.6096 | M25: =K25+0.0254 -> 1.2494 | N25: =PI()*(M25*M25-K25*K25)/4 -> 0.049342137 | O25: =N25*L25 -> 0.030078967 | P25: 8000 | Q25: =P25*O25 -> 240.63173
A26: K-112 | B26: Centrifugal compressor | C26: Power, kW | D26: 567.5542 | E26: 580000 | F26: 20000 | G26: 0.6 | H26: =(E26+(F26*(D26^G26)))/1000000 -> 1.4783269 | J26: T-103 | K26: 1.6795 | L26: =0.6096*2 -> 1.2192 | M26: =K26+0.0254 -> 1.7049 | N26: =PI()*(M26*M26-K26*K26)/4 -> 0.067515779 | O26: =N26*L26 -> 0.082315238 | P26: 8000 | Q26: =P26*O26 -> 658.5219
A27: K-113 | B27: Centrifugal compressor | C27: Power, kW | D27: 930.9868 | E27: 580000 | F27: 20000 | G27: 0.6 | H27: =(E27+(F27*(D27^G27)))/1000000 -> 1.788916
A28: K-114 | B28: Centrifugal compressor | C28: Power, kW | D28: 2559.6749 | E28: 580000 | F28: 20000 | G28: 0.6 | H28: =(E28+(F28*(D28^G28)))/1000000 -> 2.7978945
A29: K-115 | B29: Centrifugal compressor | C29: Power, kW | D29: 2937.9039 | E29: 580000 | F29: 20000 | G29: 0.6 | H29: =(E29+(F29*(D29^G29)))/1000000 -> 2.9890874
A30: K-116 | B30: Centrifugal compressor | C30: Power, kW | D30: 3007.8458 | E30: 580000 | F30: 20000 | G30: 0.6 | H30: =(E30+(F30*(D30^G30)))/1000000 -> 3.0233368
B31: Total | H31: =SUM(H14:H30) -> 34.531642
A32: Pumps
A33: P-100 | B33: Centrifugal pump | C33: Flow, litres/s | D33: =5.52953103098377*1000/3600 -> 1.5359808 | E33: 8000 | F33: 240 | G33: 0.9 | H33: =(E33+(F33*(D33^G33)))/1000000 -> 0.0083531494
A34: P-101 | B34: Centrifugal pump | C34: Flow, litres/s | D34: =38.2139638901829*1000/3600 -> 10.61499 | E34: 8000 | F34: 240 | G34: 0.9 | H34: =(E34+(F34*(D34^G34)))/1000000 -> 0.010011587
A35: P-102 | B35: Centrifugal pump | C35: Flow, litres/s | D35: =39.9115952363907*1000/3600 -> 11.086554 | E35: 8000 | F35: 240 | G35: 0.9 | H35: =(E35+(F35*(D35^G35)))/1000000 -> 0.010091839
B36: Total | H36: =SUM(H33:H35) -> 0.028456575
A37: Heat exchangers
A38: E-191 | B38: U tube HEX | C38: Area | D38: 876.29109 | E38: 28000 | F38: 54 | G38: 1.2 | H38: =(E38+(F38*(D38^G38)))/1000000 -> 0.21147286
A39: E-191 | B39: U tube HEX | C39: Area | D39: 876.29109 | E39: 28000 | F39: 54 | G39: 1.2 | H39: =(E39+(F39*(D39^G39)))/1000000 -> 0.21147286
A40: E-191 | B40: U tube HEX | C40: Area | D40: 876.29109 | E40: 28000 | F40: 54 | G40: 1.2 | H40: =(E40+(F40*(D40^G40)))/1000000 -> 0.21147286
A41: E-189 | B41: U tube HEX | C41: Area | D41: 63.273519 | E41: 28000 | F41: 54 | G41: 1.2 | H41: =(E41+(F41*(D41^G41)))/1000000 -> 0.035831774
A42: E-182 | B42: U tube HEX | C42: Area | D42: 224.38567 | E42: 28000 | F42: 54 | G42: 1.2 | H42: =(E42+(F42*(D42^G42)))/1000000 -> 0.06377568
...

Sheet Production costs
A4: Description | B4: Assumption | C4: M$/year
A5: Labor Costs
A6: Operating labor | B6: 9 shift positions, 9 operators/shift | C6: =50000*9*9/1000000 -> 4.05
A7: Supervision | B7: 25% of operating Labor | C7: =0.25*C6 -> 1.0125
A8: Direct overhead | B8: 45% of labor and supervision | C8: =0.45*(C6+C7) -> 2.278125
C9: =SUM(C6:C8) -> 7.340625
A10: Maintanance Costs
A11: Maintanance | B11: 3% of the installed capital cost | C11: =0.03*CAPEX!B199 -> 7.8345824
C12: =C11 -> 7.8345824
A13: Overhead Expenses
A14: Plant overhead | B14: 65% of labor and maintanace | C14: =0.65*(C6+C7+C8+C11) -> 9.8638848
A15: Tax & Insurance | B15: 2% of installed cost and offsites | C15: =0.02*(CAPEX!B199+CAPEX!B200) -> 6.7899714
C16: =SUM(C14:C15) -> 16.653856
A17: Interest
A18: Interest on debit | B18: 6% of working capital | C18: =0.06*CAPEX!B204 -> 4.277682
C19: =C18 -> 4.277682
A20: Total fixed production costs | C20: =C9+C12+C16+C19 -> 36.106746

Sheet Catalyst costs
A1: Propanol produced | D1: 58559.194 | E1: kg/hr
A4: Unit operation | B4: Catalyst used | C4: kg/hr | D4: $/kg | E4: $/hr | F4: M$/year
A5: Hydroformylation | B5: Rh/PPh3 | C5: 0.0081 | D5: 286000 | E5: =C5*D5 -> 2316.6 | F5: =E5/10^6*8000 -> 18.5328 | G5: Sigma Aldrich: https://www.sigmaaldrich.com/US/en/product/aldrich/225665

Sheet OPEX
B3: Material | C3: Unit | D3: Quantity | E3: Price ($/unit) | F3: Total cost | G3: 2019 costs | H3: Reference
B4: Raw material costs | K4: $/cu. ft | L4: $/MJ | M4: $/kg
B5: Carbon dioxide - NG CCU | C5: ton/hr | D5: =42148.0904323578/1000 -> 42.14809 | E5: 80.3 | F5: =E5*D5 -> 3384.4917 | G5: =F5 -> 3384.4917 | H5: Iasonas 2020 | J5: Natural gas | K5: 0.013 | L5: =K5/1.06 -> 0.012264151 | M5: =L5*55 -> 0.6745283
B6: Hydrogen - Wind | C6: ton/hr | D6: =5829.71870176398/1000 -> 5.8297187 | E6: 3560 | F6: =E6*D6 -> 20753.799 | G6: =F6 -> 20753.799 | H6: Parkinson 2019
B7: Ethylene | C7: ton/hr | D7: =27826.8289304375/1000 -> 27.826829 | E7: 1293 | F7: =E7*D7 -> 35980.09 | G7: =F7 -> 35980.09 | H7: Iasonas 2020
B8: Total | G8: =SUM(G5:G7) -> 60118.38
B9: Utility costs
B10: Cooling water | C10: m3/hr | D10: =16421602.7279223/1000 -> 16421.603 | E10: =3.6/100 -> 0.036 | F10: =E10*D10 -> 591.1777 | G10: =F10 -> 591.1777 | H10: Iasonas 2020
B11: Electricity | C11: MWh | D11: =27835.0537109595/1000 -> 27.835054 | E11: 69.6 | F11: =E11*D11 -> 1937.3197 | G11: =F11 -> 1937.3197 | H11: Iasonas 2020
B12: Fired heat - natural gas | C12: ton/hr | D12: =2018.00390320268/1000 -> 2.0180039 | E12: =M5*1000 -> 674.5283 | F12: =E12*D12 -> 1361.2007 | G12: =F12 -> 1361.2007 | H12: EIA natural gas (@55 MJ/kg)
B13: Total | G13: =SUM(G10:G12) -> 3889.6982
B14: Additional costs (purge,etc)
B15: Wastewater treatment | C15: m3/hr | D15: =17008.5900537084/1000 -> 17.00859 | E15: 1.6 | F15: =E15*D15 -> 27.213744 | G15: =F15 -> 27.213744 | H15: Iasonas 2020
B16: Flue gas emissions | C16: ton/hr | D16: =359.543844527518/1000 -> 0.35954384 | E16: 200 | F16: =E16*D16 -> 71.908769 | G16: =F16*C27/C26 -> 72.433389 | H16: Turton 2018
B17: Total | G17: =SUM(G15:G16) -> 99.647133
B18: Products sold
B19: Steam | C19: ton/hr | D19: =-22639.240068494/1000 -> -22.63924 | E19: 15.6 | F19: =E19*D19 -> -353.17215 | G19: =F19 -> -353.17215 | H19: Iasonas 2020
B20: Total | G20: =SUM(G19) -> -353.17215
B21: Catalyst costs | C21: M$/year | G21: =SUM('Catalyst costs'!F5) -> 18.5328 | H21: Refer catalyst costs sheet
B22: Total OPEX | C22: M$/year | G22: =(G8+G13+G17+G20)*8000/1000000+G$21 -> 528.56923
B24: Reference Data
B25: CEPCI 2008 | C25: 575.4
B26: CEPCI 2018 | C26: 603.1
B27: CEPCI 2019 | C27: 607.5
B28: CEPCI 2021 | C28: 776.3
B29: CEPCI 2022 | C29: 803.6

Sheet Summary
B3: Purchased equipment cost 2019 (M$/year) | C3: =SUM(CAPEX!B198) -> 69.826937 | E3: CAPEX summary | J3: CAPEX short summary
B4: Installed capital cost | C4: =SUM(CAPEX!B199) -> 261.15275 | E4: Unit operation | F4: Contribution 2010 | G4: Contribution 2019 | H4: CAPEX [M$/year] | J4: Unit operation | K4: CAPEX [M$/year]
B5: Offsites (OS) | C5: =SUM(CAPEX!B200) -> 78.345824 | E5: Compressors | F5: =CAPEX!H31 -> 34.531642 | G5: =F5*CAPEX!$B$197/CAPEX!$B$196 -> 39.365683 | H5: =(G5*CAPEX!$C$203+Summary!G5*CAPEX!$C$203*0.15)*CAPEX!$B$208 -> 39.288794 | J5: Compressors | K5: =H5 -> 39.288794
B6: Design and engineering (D&E) | C6: =SUM(CAPEX!B201) -> 101.84957 | E6: Pumps | F6: =CAPEX!H36 -> 0.028456575 | G6: =F6*CAPEX!$B$197/CAPEX!$B$196 -> 0.032440175 | H6: =(G6*CAPEX!$C$203+Summary!G6*CAPEX!$C$203*0.15)*CAPEX!$B$208 -> 0.032376814 | J6: Pumps | K6: =H6 -> 0.032376814
B7: Contingency (X) | C7: =SUM(CAPEX!B202) -> 33.949857 | E7: Heat exchangers | F7: =CAPEX!H160 -> 19.156225 | G7: =F7*CAPEX!$B$197/CAPEX!$B$196 -> 21.83788 | H7: =(G7*CAPEX!$C$203+Summary!G7*CAPEX!$C$203*0.15)*CAPEX!$B$208 -> 21.795227 | J7: Heat exchangers | K7: =H7 -> 21.795227
B8: Fixed capital investment | C8: =SUM(CAPEX!B203) -> 475.298 | E8: Reactors | F8: =CAPEX!H165 -> 4.1811995 | G8: =F8*CAPEX!$B$197/CAPEX!$B$196 -> 4.7665203 | H8: =(G8*CAPEX!$C$203+Summary!G8*CAPEX!$C$203*0.15)*CAPEX!$B$208 -> 4.7572104 | J8: Reactors | K8: =H8 -> 4.7572104
B9: Working capital | C9: =SUM(CAPEX!B204) -> 71.2947 | E9: Flash separators | F9: =CAPEX!H177 -> 3.131704 | G9: =F9*CAPEX!$B$197/CAPEX!$B$196 -> 3.5701073 | H9: =(G9*CAPEX!$C$203+Summary!G9*CAPEX!$C$203*0.15)*CAPEX!$B$208 -> 3.5631343 | J9: Flash separators | K9: =H9 -> 3.5631343
B10: Total investment | C10: =SUM(CAPEX!B205) -> 546.5927 | E10: Columns | F10: =CAPEX!H181+CAPEX!H185+CAPEX!H189+CAPEX!H193 -> 0.22307781 | G10: =F10*CAPEX!$B$197/CAPEX!$B$196 -> 0.25430619 | H10: =(G10*CAPEX!$C$203+Summary!G10*CAPEX!$C$203*0.15)*CAPEX!$B$208 -> 0.25380949 | J10: Columns | K10: =H10 -> 0.25380949
B11: Labor costs | C11: =SUM('Production costs'!C9) -> 7.340625 | E11: Total | F11: =SUM(F5:F10) -> 61.252304 | G11: =SUM(G5:G10) -> 69.826937 | H11: =SUM(H5:H10) -> 69.690552 | J11: Total | K11: =SUM(K5:K10) -> 69.690552
B12: Maintanance costs | C12: =SUM('Production costs'!C12) -> 7.8345824
B13: Overhead expenses | C13: =SUM('Production costs'!C16) -> 16.653856 | E13: Production costs summary | J13: Production costs short summary
B14: Interest | C14: =SUM('Production costs'!C19) -> 4.277682 | E14: Category | F14: M$/year | J14: Category | K14: M$/year
B15: Project lifetime | C15: =SUM(CAPEX!B206) -> 25 | E15: Operating labor | F15: ='Production costs'!C6 -> 4.05 | J15: Labor | K15: =F15+F16+F17 -> 7.340625
B16: Interest rate | C16: =SUM(CAPEX!B207) -> 0.12 | E16: Supervision | F16: ='Production costs'!C7 -> 1.0125 | J16: Maintanance | K16: =F18 -> 7.8345824
B17: ACCR | C17: =SUM(CAPEX!B208) -> 0.12749997 | E17: Direct overhead | F17: ='Production costs'!C8 -> 2.278125 | J17: Overhead | K17: =F19+F20 -> 16.653856
B18: CAPEX (M$/year) | C18: =SUM(CAPEX!B210) -> 69.690552 | E18: Maintanance | F18: ='Production costs'!C11 -> 7.8345824 | J18: Interest | K18: =F21 -> 4.277682
B19: Fixed production costs (M$/year) | C19: ='Production costs'!C20 -> 36.106746 | E19: Plant overhead | F19: ='Production costs'!C14 -> 9.8638848 | J19: Total | K19: =SUM(K15:K18) -> 36.106746
B20: OPEX (M$/year) | C20: =OPEX!G22 -> 528.56923 | E20: Tax & Insurance | F20: ='Production costs'!C15 -> 6.7899714
B21: Total expenses (M$/year) | C21: =($C$18+$C$19+C20) -> 634.36652 | E21: Interest on debit | F21: ='Production costs'!C18 -> 4.277682
B22: Total expenses ($/hr) | C22: =(C21)*1000000/8000 -> 79295.815 | E22: Total | F22: =SUM(F15:F21) -> 36.106746
B23: Total propanol produced (kg/hr) | C23: 58559.194
B24: Cost of propanol per kg | C24: =C22/C23 -> 1.3541138 | E24: OPEX short summary
B25: Cost of propanol per ton | C25: =C24*1000 -> 1354.1138 | E25: Category | F25: M$/year
E26: Carbon dioxide | F26: =OPEX!G5*8000/10^6 -> 27.075933
E27: Hydrogen | F27: =OPEX!G6*8000/10^6 -> 166.03039
E28: Ethylene | F28: =OPEX!G7*8000/10^6 -> 287.84072
E29: Cooling water | F29: =OPEX!G10*8000/10^6 -> 4.7294216
E30: Electricity | F30: =OPEX!G11*8000/10^6 -> 15.498558
E31: Fired heat - natural gas | F31: =OPEX!G12*8000/10^6 -> 10.889606
E32: Wastewater treatment | F32: =OPEX!G15*8000/10^6 -> 0.21770995
E33: Flue gas emissions | F33: =OPEX!G16*8000/10^6 -> 0.57946711
E34: Steam | F34: =OPEX!G19*8000/10^6 -> -2.8253772
E35: Catalyst | F35: =OPEX!G21 -> 18.5328
E36: Total | F36: =SUM(F26:F35) -> 528.56923
