Workbook

Sheet CAPEX
A1: Cost factors
A2: Equipment erection | B2: fer | C2: 0.3
A3: Piping | B3: fp | C3: 0.8
A4: Instrumentation and control | B4: fi | C4: 0.3
A5: Electrical | B5: fel | C5: 0.2
A6: Civil | B6: fc | C6: 0.3
A7: Structures and buildings | B7: fs | C7: 0.2
A8: Lagging and paint | B8: fl | C8: 0.1
A9: Material factor for 304 SS | B9: fm | C9: 1.3
A12: Equipment | B12: Equipment approximated as | C12: Dimension needed | D12: Value | E12: a | F12: b | G12: n | H12: Purchased Cost (Ce,i,a) | J12: Equipment | K12: Internal diameter (m) | L12: h (m) | M12: External diameter (m) | N12: Area for shell (m2) | O12: Volume | P12: Density (kg/m3) | Q12: Shell mass (kg)
A13: Compressors | J13: V-100 | K13: 3.81 | L13: 13.33 | M13: =K13+0.0254 -> 3.8354 | N13: =PI()*(M13*M13-K13*K13)/4 -> 0.15251895 | O13: =N13*L13 -> 2.0330776 | P13: 8000 | Q13: =P13*O13 -> 16264.621
A14: K-100 | B14: Centrifugal compressor | C14: Power, kW | D14: 3888.735 | E14: 580000 | F14: 20000 | G14: 0.6 | H14: =(E14+(F14*(D14^G14)))/1000000 -> 3.4304603 | J14: V-101 | K14: 16.31 | L14: 57.07 | M14: =K14+0.0254 -> 16.3354 | N14: =PI()*(M14*M14-K14*K14)/4 -> 0.65124678 | O14: =N14*L14 -> 37.166654 | P14: 8000 | Q14: =P14*O14 -> 297333.23
A15: K-101 | B15: Centrifugal compressor | C15: Power, kW | D15: 4195.0303 | E15: 580000 | F15: 20000 | G15: 0.6 | H15: =(E15+(F15*(D15^G15)))/1000000 -> 3.5631223 | J15: V-102 | K15: 16.1544 | L15: 56.5404 | M15: =K15+0.0254 -> 16.1798 | N15: =PI()*(M15*M15-K15*K15)/4 -> 0.64503862 | O15: =N15*L15 -> 36.470742 | P15: 8000 | Q15: =P15*O15 -> 291765.93
A16: K-102 | B16: Centrifugal compressor | C16: Power, kW | D16: 471.47948 | E16: 580000 | F16: 20000 | G16: 0.6 | H16: =(E16+(F16*(D16^G16)))/1000000 -> 1.3837254 | J16: V-103 | K16: 1.524 | L16: 8.382 | M16: =K16+0.0254 -> 1.5494 | N16: =PI()*(M16*M16-K16*K16)/4 -> 0.061311605 | O16: =N16*L16 -> 0.51391387 | P16: 8000 | Q16: =P16*O16 -> 4111.311
A17: K-103 | B17: Centrifugal compressor | C17: Power, kW | D17: 9549.5532 | E17: 580000 | F17: 20000 | G17: 0.6 | H17: =(E17+(F17*(D17^G17)))/1000000 -> 5.4667467 | J17: T-101 | K17: 5.234 | L17: =0.6096*42 -> 25.6032 | M17: =K17+0.0254 -> 5.2594 | N17: =PI()*(M17*M17-K17*K17)/4 -> 0.20933403 | O17: =N17*L17 -> 5.3596209 | P17: 8000 | Q17: =P17*O17 -> 42876.967
A18: K-104 | B18: Centrifugal compressor | C18: Power, kW | D18: 11235.754 | E18: 580000 | F18: 20000 | G18: 0.6 | H18: =(E18+(F18*(D18^G18)))/1000000 -> 5.9675503
A19: K-105 | B19: Centrifugal compressor | C19: Power, kW | D19: 3270.2765 | E19: 580000 | F19: 20000 | G19: 0.6 | H19: =(E19+(F19*(D19^G19)))/1000000 -> 3.149098
A20: K-106 | B20: Centrifugal compressor | C20: Power, kW | D20: 282.66403 | E20: 580000 | F20: 20000 | G20: 0.6 | H20: =(E20+(F20*(D20^G20)))/1000000 -> 1.1712788
A21: K-107 | B21: Centrifugal compressor | C21: Power, kW | D21: 293.20057 | E21: 580000 | F21: 20000 | G21: 0.6 | H21: =(E21+(F21*(D21^G21)))/1000000 -> 1.1844062
A22: K-108 | B22: Centrifugal compressor | C22: Power, kW | D22: 303.7004 | E22: 580000 | F22: 20000 | G22: 0.6 | H22: =(E22+(F22*(D22^G22)))/1000000 -> 1.1973013
A23: K-109 | B23: Centrifugal compressor | C23: Power, kW | D23: 227.45811 | E23: 580000 | F23: 20000 | G23: 0.6 | H23: =(E23+(F23*(D23^G23)))/1000000 -> 1.0990042
B24: Total | H24: =SUM(H14:H23) -> 27.612694
A25: Pumps
A26: P-100 | B26: Centrifugal pump | C26: Flow, litres/s | D26: 18.64 | E26: 8000 | F26: 240 | G26: 0.9 | H26: =(E26+(F26*(D26^G26)))/1000000 -> 0.01133897
B27: Total | H27: =SUM(H26:H26) -> 0.01133897
A28: Heat exchangers
A29: E-131 | B29: U tube HEX | C29: Area | D29: 443.23626 | E29: 28000 | F29: 54 | G29: 1.2 | H29: =(E29+(F29*(D29^G29)))/1000000 -> 0.10897596
A30: E-132 | B30: U tube HEX | C30: Area | D30: =5272.74583311151/6 -> 878.79097 | E30: 28000 | F30: 54 | G30: 1.2 | H30: =(E30+(F30*(D30^G30)))/1000000 -> 0.21210113
A31: E-132 | B31: U tube HEX | C31: Area | D31: =5272.74583311151/6 -> 878.79097 | E31: 28000 | F31: 54 | G31: 1.2 | H31: =(E31+(F31*(D31^G31)))/1000000 -> 0.21210113
A32: E-132 | B32: U tube HEX | C32: Area | D32: =5272.74583311151/6 -> 878.79097 | E32: 28000 | F32: 54 | G32: 1.2 | H32: =(E32+(F32*(D32^G32)))/1000000 -> 0.21210113
A33: E-132 | B33: U tube HEX | C33: Area | D33: =5272.74583311151/6 -> 878.79097 | E33: 28000 | F33: 54 | G33: 1.2 | H33: =(E33+(F33*(D33^G33)))/1000000 -> 0.21210113
A34: E-132 | B34: U tube HEX | C34: Area | D34: =5272.74583311151/6 -> 878.79097 | E34: 28000 | F34: 54 | G34: 1.2 | H34: =(E34+(F34*(D34^G34)))/1000000 -> 0.21210113
A35: E-132 | B35: U tube HEX | C35: Area | D35: =5272.74583311151/6 -> 878.79097 | E35: 28000 | F35: 54 | G35: 1.2 | H35: =(E35+(F35*(D35^G35)))/1000000 -> 0.21210113
A36: E-133 | B36: U tube HEX | C36: Area | D36: =1292.9121037104/2 -> 646.45605 | E36: 28000 | F36: 54 | G36: 1.2 | H36: =(E36+(F36*(D36^G36)))/1000000 -> 0.1553622
A37: E-133 | B37: U tube HEX | C37: Area | D37: =1292.9121037104/2 -> 646.45605 | E37: 28000 | F37: 54 | G37: 1.2 | H37: =(E37+(F37*(D37^G37)))/1000000 -> 0.1553622
A38: E-134 | B38: U tube HEX | C38: Area | D38: 765.73162 | E38: 28000 | F38: 54 | G38: 1.2 | H38: =(E38+(F38*(D38^G38)))/1000000 -> 0.18405786
A39: E-135 | B39: U tube HEX | C39: Area | D39: =3110.28839969224/4 -> 777.5721 | E39: 28000 | F39: 54 | G39: 1.2 | H39: =(E39+(F39*(D39^G39)))/1000000 -> 0.18695806
A40: E-135 | B40: U tube HEX | C40: Area | D40: =3110.28839969224/4 -> 777.5721 | E40: 28000 | F40: 54 | G40: 1.2 | H40: =(E40+(F40*(D40^G40)))/1000000 -> 0.18695806
A41: E-135 | B41: U tube HEX | C41: Area | D41: =3110.28839969224/4 -> 777.5721 | E41: 28000 | F41: 54 | G41: 1.2 | H41: =(E41+(F41*(D41^G41)))/1000000 -> 0.18695806
A42: E-135 | B42: U tube HEX | C42: Area | D42: =3110.28839969224/4 -> 777.5721 | E42: 28000 | F42: 54 | G42: 1.2 | H42: =(E42+(F42*(D42^G42)))/1000000 -> 0.18695806
...

Sheet Production costs
A4: Description | B4: Assumption | C4: M$/year
A5: Labor Costs
A6: Operating labor | B6: 9 shift positions, 9 operators/shift | C6: =50000*9*9/1000000 -> 4.05
A7: Supervision | B7: 25% of operating Labor | C7: =0.25*C6 -> 1.0125
A8: Direct overhead | B8: 45% of labor and supervision | C8: =0.45*(C6+C7) -> 2.278125
C9: =SUM(C6:C8) -> 7.340625
A10: Maintanance Costs
A11: Maintanance | B11: 3% of the installed capital cost | C11: =0.03*CAPEX!B342 -> 19.007239
C12: =C11 -> 19.007239
A13: Overhead Expenses
A14: Plant overhead | B14: 65% of labor and maintanace | C14: =0.65*(C6+C7+C8+C11) -> 17.126112
A15: Tax & Insurance | B15: 2% of installed cost and offsites | C15: =0.02*(CAPEX!B342+CAPEX!B343) -> 16.47294
C16: =SUM(C14:C15) -> 33.599052
A17: Interest
A18: Interest on debit | B18: 6% of working capital | C18: =0.06*CAPEX!B347 -> 10.377953
C19: =C18 -> 10.377953
A20: Total fixed production costs | C20: =C9+C12+C16+C19 -> 70.324869

Sheet OPEX
B3: Material | C3: Unit | D3: Quantity | E3: Price ($/unit) | F3: Total cost | G3: 2022 costs | H3: Reference
B4: Raw material costs | K4: $/cu. ft | L4: $/MJ | M4: $/kg
B5: Biogas | C5: ton/hr | D5: =105460.319659424/1000 -> 105.46032 | E5: 150.8618 | F5: =E5*D5 -> 15909.934 | G5: =F5*C32/C29 -> 21199.175 | H5: IEA 2018 | J5: Natural gas | K5: =13.4/1000 -> 0.0134 | L5: =K5/1.06 -> 0.012641509 | M5: =L5*55 -> 0.69528302
B6: Carbon dioxide - NG CCU | C6: ton/hr | D6: =13643.0072402954/1000 -> 13.643007 | E6: 80.3 | F6: =E6*D6 -> 1095.5335 | G6: =F6*C32/C30 -> 1449.1699 | H6: Iasonas 2020
B7: Ethylene | C7: ton/hr | D7: 0 | E7: 1293 | F7: =E7*D7 -> 0 | G7: =F7*C32/C30 -> 0 | H7: Iasonas 2020
B8: Hydrogen | C8: ton/hr | D8: 0 | E8: 2090 | F8: =E8*D8 -> 0 | G8: =F8*C32/C30 -> 0 | H8: Iasonas 2020
B9: Total | G9: =SUM(G5:G8) -> 22648.345
B10: Utility costs
B11: Cooling water | C11: m3/hr | D11: =33280979.3147413/1000 -> 33280.979 | E11: =3.6/100 -> 0.036 | F11: =E11*D11 -> 1198.1153 | G11: =F11*C32/C30 -> 1584.8649 | H11: Iasonas 2020
B12: Electricity | C12: MWh | D12: =33732.628163305/1000 -> 33.732628 | E12: 69.6 | F12: =E12*D12 -> 2347.7909 | G12: =F12*C32/C30 -> 3105.654 | H12: Iasonas 2020
B13: Fired heat - natural gas | C13: ton/hr | D13: =13579.1453483624/1000 -> 13.579145 | E13: 524 | F13: =E13*D13 -> 7115.4722 | G13: =F13*C32/C31 -> 7365.7007 | H13: Europa 2021
B14: Steam | C14: ton/hr | D14: =92155.8484079724/1000 -> 92.155848 | E14: 15.6 | F14: =E14*D14 -> 1437.6312 | G14: =F14*C32/C30 -> 1901.6962 | H14: Iasonas 2020
B15: Total | G15: =SUM(G11:G14) -> 13957.916
B16: Additional costs (purge,etc)
B17: CO2 capture and storage | C17: ton/hr | D17: 0 | E17: 15 | F17: =E17*D17 -> 0 | G17: =F17*C$32/C$28 -> 0 | H17: Dooley 2008 (pg. 5)
B18: Wastewater treatment | C18: m3/hr | D18: =49617.3631348832/1000 -> 49.617363 | E18: 1.6 | F18: =E18*D18 -> 79.387781 | G18: =F18*C32/C30 -> 105.01403 | H18: Iasonas 2020
B19: Flue gas emissions | C19: ton/hr | D19: 0 | E19: 200 | F19: =E19*D19 -> 0 | G19: =F19*C32/C29 -> 0 | H19: Turton 2018 (pg. 246)
B20: Total | G20: =SUM(G17:G19) -> 105.01403
B21: Products sold
B22: Steam | C22: ton/hr | D22: 0 | E22: 15.6 | F22: =E22*D22 -> 0 | G22: =F22*C32/C30 -> 0 | H22: Iasonas 2020
B23: Total | G23: =SUM(G22) -> 0
B24: Catalyst costs | C24: M$/year | G24: 0 | H24: Refer catalyst costs sheet
B25: Total OPEX | C25: M$/year | G25: =(G9+G15+G20+G23)*8000/1000000+G$24 -> 293.6902
B27: Reference Data
B28: CEPCI 2008 | C28: 575.4
B29: CEPCI 2018 | C29: 603.1
B30: CEPCI 2019 | C30: 607.5
B31: CEPCI 2021 | C31: 776.3
B32: CEPCI 2022 | C32: 803.6

Sheet Summary
B3: Purchased equipment cost 2022 (M$/year) | C3: =SUM(CAPEX!B341) -> 169.40498 | E3: CAPEX summary | J3: CAPEX short summary
B4: Installed capital cost | C4: =SUM(CAPEX!B342) -> 633.57463 | E4: Unit operation | F4: Contribution 2010 | G4: Contribution 2022 | H4: CAPEX [M$/year] | J4: Unit operation | K4: CAPEX [M$/year]
B5: Offsites (OS) | C5: =SUM(CAPEX!B343) -> 190.07239 | E5: Compressors | F5: =CAPEX!H24 -> 27.612694 | G5: =F5*CAPEX!$B$340/CAPEX!$B$339 -> 41.639258 | H5: =(G5*CAPEX!$C$346+Summary!G5*CAPEX!$C$346*0.15)*CAPEX!$B$351 -> 41.557929 | J5: Compressors | K5: =H5 -> 41.557929
B6: Design and engineering (D&E) | C6: =SUM(CAPEX!B344) -> 247.09411 | E6: Pumps | F6: =CAPEX!H27 -> 0.01133897 | G6: =F6*CAPEX!$B$340/CAPEX!$B$339 -> 0.017098886 | H6: =(G6*CAPEX!$C$346+Summary!G6*CAPEX!$C$346*0.15)*CAPEX!$B$351 -> 0.017065489 | J6: Pumps | K6: =H6 -> 0.017065489
B7: Contingency (X) | C7: =SUM(CAPEX!B345) -> 82.364702 | E7: Heat exchangers | F7: =CAPEX!H317 -> 64.12177 | G7: =F7*CAPEX!$B$340/CAPEX!$B$339 -> 96.69404 | H7: =(G7*CAPEX!$C$346+Summary!G7*CAPEX!$C$346*0.15)*CAPEX!$B$351 -> 96.505179 | J7: Heat exchangers | K7: =H7 -> 96.505179
B8: Fixed capital investment | C8: =SUM(CAPEX!B346) -> 1153.1058 | E8: Reactors | F8: =CAPEX!H324 -> 11.216549 | G8: =F8*CAPEX!$B$340/CAPEX!$B$339 -> 16.914278 | H8: =(G8*CAPEX!$C$346+Summary!G8*CAPEX!$C$346*0.15)*CAPEX!$B$351 -> 16.881241 | J8: Reactors | K8: =H8 -> 16.881241
B9: Working capital | C9: =SUM(CAPEX!B347) -> 172.96588 | E9: Flash separators | F9: =CAPEX!H332 -> 8.3066341 | G9: =F9*CAPEX!$B$340/CAPEX!$B$339 -> 12.526198 | H9: =(G9*CAPEX!$C$346+Summary!G9*CAPEX!$C$346*0.15)*CAPEX!$B$351 -> 12.501732 | J9: Flash separators | K9: =H9 -> 12.501732
B10: Total investment | C10: =SUM(CAPEX!B348) -> 1326.0717 | E10: Columns | F10: =CAPEX!H336 -> 1.0703815 | G10: =F10*CAPEX!$B$340/CAPEX!$B$339 -> 1.6141088 | H10: =(G10*CAPEX!$C$346+Summary!G10*CAPEX!$C$346*0.15)*CAPEX!$B$351 -> 1.6109562 | J10: Columns | K10: =H10 -> 1.6109562
B11: Labor costs | C11: =SUM('Production costs'!C9) -> 7.340625 | E11: Total | F11: =SUM(F5:F10) -> 112.33937 | G11: =SUM(G5:G10) -> 169.40498 | H11: =SUM(H5:H10) -> 169.0741 | J11: Total | K11: =SUM(K5:K10) -> 169.0741
B12: Maintanance costs | C12: =SUM('Production costs'!C12) -> 19.007239
B13: Overhead expenses | C13: =SUM('Production costs'!C16) -> 33.599052 | E13: Production costs summary | J13: Production costs short summary
B14: Interest | C14: =SUM('Production costs'!C19) -> 10.377953 | E14: Category | F14: M$/year | J14: Category | K14: M$/year
B15: Project lifetime | C15: =SUM(CAPEX!B349) -> 25 | E15: Operating labor | F15: ='Production costs'!C6 -> 4.05 | J15: Labor | K15: =F15+F16+F17 -> 7.340625
B16: Interest rate | C16: =SUM(CAPEX!B350) -> 0.12 | E16: Supervision | F16: ='Production costs'!C7 -> 1.0125 | J16: Maintanance | K16: =F18 -> 19.007239
B17: ACCR | C17: =SUM(CAPEX!B351) -> 0.12749997 | E17: Direct overhead | F17: ='Production costs'!C8 -> 2.278125 | J17: Overhead | K17: =F19+F20 -> 33.599052
B18: CAPEX (M$/year) | C18: =SUM(CAPEX!B353) -> 169.0741 | E18: Maintanance | F18: ='Production costs'!C11 -> 19.007239 | J18: Interest | K18: =F21 -> 10.377953
B19: Fixed production costs (M$/year) | C19: ='Production costs'!C20 -> 70.324869 | E19: Plant overhead | F19: ='Production costs'!C14 -> 17.126112 | J19: Total | K19: =SUM(K15:K18) -> 70.324869
B20: OPEX (M$/year) | C20: =OPEX!G25 -> 293.6902 | E20: Tax & Insurance | F20: ='Production costs'!C15 -> 16.47294
B21: Total expenses (M$/year) | C21: =($C$18+$C$19+C20) -> 533.08917 | E21: Interest on debit | F21: ='Production costs'!C18 -> 10.377953
B22: Total expenses ($/hr) | C22: =(C21)*1000000/8000 -> 66636.147 | E22: Total | F22: =SUM(F15:F21) -> 70.324869
B23: Total methanol produced (kg/hr) | C23: 76989.801
B24: Cost of methanol per kg | C24: =C22/C23 -> 0.86551914 | E24: OPEX short summary
B25: Cost of methanol per ton | C25: =C24*1000 -> 865.51914 | E25: Category | F25: M$/year
E26: Biogas | F26: =OPEX!G5*8000/10^6 -> 169.5934
E27: Carbon dioxide | F27: =OPEX!G6*8000/10^6 -> 11.593359
E28: Ethylene | F28: =OPEX!G7*8000/10^6 -> 0
E29: Hydrogen | F29: =OPEX!G8*8000/10^6 -> 0
E30: Cooling water | F30: =OPEX!G11*8000/10^6 -> 12.678919
E31: Electricity | F31: =OPEX!G12*8000/10^6 -> 24.845232
E32: Fired heat - natural gas | F32: =OPEX!G13*8000/10^6 -> 58.925605
E33: CO2 capture and storage | F33: =OPEX!G17*8000/10^6 -> 0
E34: Wastewater treatment | F34: =OPEX!G18*8000/10^6 -> 0.84011221
E35: Flue gas emissions | F35: =OPEX!G19*8000/10^6 -> 0
E36: Steam | F36: =OPEX!G14*8000/10^6 -> 15.21357
E37: Catalyst | F37: =OPEX!G24 -> 0
E38: Total | F38: =SUM(F26:F37) -> 293.6902
E40: Overall
E41: Category | F41: Contribution $/t | G41: Required (unit/hr) | H41: Unit | I41: %
E42: Natural gas | F42: 0 | G42: 0 | H42: ton/hr | I42: =F42/$F$58*100 -> 0
E43: Carbon dioxide | F43: =F27*10^9/8000/$C$23 -> 18.822881 | G43: 0 | H43: ton/hr | I43: =F43/$F$58*100 -> 2.1747504
...
